INFO 07/Oct/2019 08:23:47 autoreload [django.utils.autoreload:run_with_reloader:597] Watching for file changes with StatReloader
INFO 07/Oct/2019 08:24:23 autoreload [django.utils.autoreload:run_with_reloader:597] Watching for file changes with StatReloader
INFO 07/Oct/2019 08:25:25 autoreload [django.utils.autoreload:trigger_reload:217] /Users/welcome/Developments/repos/recommender_system_api/config/settings/base.py changed, reloading.
INFO 07/Oct/2019 08:25:25 autoreload [django.utils.autoreload:run_with_reloader:597] Watching for file changes with StatReloader
INFO 07/Oct/2019 08:25:29 autoreload [django.utils.autoreload:trigger_reload:217] /Users/welcome/Developments/repos/recommender_system_api/config/settings/base.py changed, reloading.
INFO 07/Oct/2019 08:25:29 autoreload [django.utils.autoreload:run_with_reloader:597] Watching for file changes with StatReloader
INFO 07/Oct/2019 08:25:34 autoreload [django.utils.autoreload:run_with_reloader:597] Watching for file changes with StatReloader
INFO 07/Oct/2019 08:25:45 autoreload [django.utils.autoreload:trigger_reload:217] /Users/welcome/Developments/repos/recommender_system_api/config/settings/base.py changed, reloading.
INFO 07/Oct/2019 08:25:46 autoreload [django.utils.autoreload:trigger_reload:217] /Users/welcome/Developments/repos/recommender_system_api/config/settings/base.py changed, reloading.
INFO 07/Oct/2019 08:25:46 autoreload [django.utils.autoreload:run_with_reloader:597] Watching for file changes with StatReloader
INFO 07/Oct/2019 08:25:46 autoreload [django.utils.autoreload:run_with_reloader:597] Watching for file changes with StatReloader
INFO 07/Oct/2019 08:25:52 autoreload [django.utils.autoreload:trigger_reload:217] /Users/welcome/Developments/repos/recommender_system_api/config/settings/base.py changed, reloading.
INFO 07/Oct/2019 08:25:52 autoreload [django.utils.autoreload:trigger_reload:217] /Users/welcome/Developments/repos/recommender_system_api/config/settings/base.py changed, reloading.
INFO 07/Oct/2019 08:25:53 autoreload [django.utils.autoreload:run_with_reloader:597] Watching for file changes with StatReloader
INFO 07/Oct/2019 08:25:53 autoreload [django.utils.autoreload:run_with_reloader:597] Watching for file changes with StatReloader
INFO 07/Oct/2019 08:27:17 autoreload [django.utils.autoreload:trigger_reload:217] /Users/welcome/Developments/repos/recommender_system_api/config/settings/base.py changed, reloading.
INFO 07/Oct/2019 08:27:17 autoreload [django.utils.autoreload:trigger_reload:217] /Users/welcome/Developments/repos/recommender_system_api/config/settings/base.py changed, reloading.
INFO 07/Oct/2019 08:27:17 autoreload [django.utils.autoreload:run_with_reloader:597] Watching for file changes with StatReloader
INFO 07/Oct/2019 08:27:18 autoreload [django.utils.autoreload:run_with_reloader:597] Watching for file changes with StatReloader
INFO 07/Oct/2019 08:27:28 autoreload [django.utils.autoreload:trigger_reload:217] /Users/welcome/Developments/repos/recommender_system_api/config/settings/base.py changed, reloading.
INFO 07/Oct/2019 08:27:28 autoreload [django.utils.autoreload:trigger_reload:217] /Users/welcome/Developments/repos/recommender_system_api/config/settings/base.py changed, reloading.
INFO 07/Oct/2019 08:27:28 autoreload [django.utils.autoreload:run_with_reloader:597] Watching for file changes with StatReloader
INFO 07/Oct/2019 08:27:29 autoreload [django.utils.autoreload:run_with_reloader:597] Watching for file changes with StatReloader
INFO 07/Oct/2019 08:28:19 autoreload [django.utils.autoreload:run_with_reloader:597] Watching for file changes with StatReloader
INFO 07/Oct/2019 08:31:03 autoreload [django.utils.autoreload:trigger_reload:217] /Users/welcome/Developments/repos/recommender_system_api/recommender_system_api/utils/connections.py changed, reloading.
INFO 07/Oct/2019 08:31:04 autoreload [django.utils.autoreload:run_with_reloader:597] Watching for file changes with StatReloader
INFO 07/Oct/2019 08:31:11 autoreload [django.utils.autoreload:trigger_reload:217] /Users/welcome/Developments/repos/recommender_system_api/recommender_system_api/utils/connections.py changed, reloading.
INFO 07/Oct/2019 08:31:12 autoreload [django.utils.autoreload:run_with_reloader:597] Watching for file changes with StatReloader
INFO 07/Oct/2019 08:31:26 autoreload [django.utils.autoreload:trigger_reload:217] /Users/welcome/Developments/repos/recommender_system_api/recommender_system_api/vendors/vendor_hybrid_recommendation.py changed, reloading.
INFO 07/Oct/2019 08:31:27 autoreload [django.utils.autoreload:run_with_reloader:597] Watching for file changes with StatReloader
INFO 07/Oct/2019 08:33:14 autoreload [django.utils.autoreload:run_with_reloader:597] Watching for file changes with StatReloader
INFO 07/Oct/2019 08:34:54 autoreload [django.utils.autoreload:trigger_reload:217] /Users/welcome/Developments/repos/recommender_system_api/config/settings/dev.py changed, reloading.
INFO 07/Oct/2019 08:34:54 autoreload [django.utils.autoreload:trigger_reload:217] /Users/welcome/Developments/repos/recommender_system_api/config/settings/dev.py changed, reloading.
INFO 07/Oct/2019 08:34:55 autoreload [django.utils.autoreload:run_with_reloader:597] Watching for file changes with StatReloader
INFO 07/Oct/2019 08:34:56 autoreload [django.utils.autoreload:run_with_reloader:597] Watching for file changes with StatReloader
INFO 07/Oct/2019 08:35:15 autoreload [django.utils.autoreload:run_with_reloader:597] Watching for file changes with StatReloader
INFO 07/Oct/2019 08:35:44 autoreload [django.utils.autoreload:run_with_reloader:597] Watching for file changes with StatReloader
INFO 07/Oct/2019 08:36:08 autoreload [django.utils.autoreload:trigger_reload:217] /Users/welcome/Developments/repos/recommender_system_api/recommender_system_api/api/views.py changed, reloading.
INFO 07/Oct/2019 08:36:09 autoreload [django.utils.autoreload:run_with_reloader:597] Watching for file changes with StatReloader
INFO 07/Oct/2019 08:36:59 autoreload [django.utils.autoreload:trigger_reload:217] /Users/welcome/Developments/repos/recommender_system_api/recommender_system_api/vendors/vendor_hybrid_recommendation.py changed, reloading.
INFO 07/Oct/2019 08:37:00 autoreload [django.utils.autoreload:run_with_reloader:597] Watching for file changes with StatReloader
INFO 07/Oct/2019 08:37:39 autoreload [django.utils.autoreload:run_with_reloader:597] Watching for file changes with StatReloader
INFO 07/Oct/2019 08:37:57 autoreload [django.utils.autoreload:trigger_reload:217] /Users/welcome/Developments/repos/recommender_system_api/recommender_system_api/vendors/vendor_hybrid_recommendation.py changed, reloading.
INFO 07/Oct/2019 08:37:58 autoreload [django.utils.autoreload:run_with_reloader:597] Watching for file changes with StatReloader
INFO 07/Oct/2019 08:45:29 autoreload [django.utils.autoreload:trigger_reload:217] /Users/welcome/Developments/recommender_env/lib/python3.6/site-packages/rake_nltk/rake.py changed, reloading.
INFO 07/Oct/2019 08:45:30 autoreload [django.utils.autoreload:run_with_reloader:597] Watching for file changes with StatReloader
INFO 07/Oct/2019 08:48:35 autoreload [django.utils.autoreload:trigger_reload:217] /Users/welcome/Developments/repos/recommender_system_api/recommender_system_api/vendors/vendor_hybrid_recommendation.py changed, reloading.
INFO 07/Oct/2019 08:48:36 autoreload [django.utils.autoreload:run_with_reloader:597] Watching for file changes with StatReloader
INFO 07/Oct/2019 08:48:58 autoreload [django.utils.autoreload:trigger_reload:217] /Users/welcome/Developments/repos/recommender_system_api/recommender_system_api/utils/words_processing.py changed, reloading.
INFO 07/Oct/2019 08:48:59 autoreload [django.utils.autoreload:run_with_reloader:597] Watching for file changes with StatReloader
INFO 07/Oct/2019 08:49:40 autoreload [django.utils.autoreload:trigger_reload:217] /Users/welcome/Developments/repos/recommender_system_api/recommender_system_api/utils/words_processing.py changed, reloading.
INFO 07/Oct/2019 08:49:41 autoreload [django.utils.autoreload:run_with_reloader:597] Watching for file changes with StatReloader
INFO 07/Oct/2019 08:51:35 autoreload [django.utils.autoreload:run_with_reloader:597] Watching for file changes with StatReloader
INFO 07/Oct/2019 08:54:51 autoreload [django.utils.autoreload:trigger_reload:217] /Users/welcome/Developments/repos/recommender_system_api/config/settings/dev.py changed, reloading.
INFO 07/Oct/2019 08:54:51 autoreload [django.utils.autoreload:trigger_reload:217] /Users/welcome/Developments/repos/recommender_system_api/config/settings/dev.py changed, reloading.
INFO 07/Oct/2019 08:54:52 autoreload [django.utils.autoreload:run_with_reloader:597] Watching for file changes with StatReloader
INFO 07/Oct/2019 08:54:52 autoreload [django.utils.autoreload:run_with_reloader:597] Watching for file changes with StatReloader
INFO 07/Oct/2019 08:57:43 autoreload [django.utils.autoreload:trigger_reload:217] /Users/welcome/Developments/repos/recommender_system_api/config/settings/dev.py changed, reloading.
INFO 07/Oct/2019 08:57:43 autoreload [django.utils.autoreload:trigger_reload:217] /Users/welcome/Developments/repos/recommender_system_api/config/settings/dev.py changed, reloading.
INFO 07/Oct/2019 08:57:43 autoreload [django.utils.autoreload:run_with_reloader:597] Watching for file changes with StatReloader
INFO 07/Oct/2019 08:57:44 autoreload [django.utils.autoreload:run_with_reloader:597] Watching for file changes with StatReloader
INFO 07/Oct/2019 08:57:54 autoreload [django.utils.autoreload:trigger_reload:217] /Users/welcome/Developments/repos/recommender_system_api/config/settings/dev.py changed, reloading.
INFO 07/Oct/2019 08:57:54 autoreload [django.utils.autoreload:trigger_reload:217] /Users/welcome/Developments/repos/recommender_system_api/config/settings/dev.py changed, reloading.
INFO 07/Oct/2019 08:57:55 autoreload [django.utils.autoreload:run_with_reloader:597] Watching for file changes with StatReloader
INFO 07/Oct/2019 08:57:55 autoreload [django.utils.autoreload:run_with_reloader:597] Watching for file changes with StatReloader
INFO 07/Oct/2019 08:58:44 autoreload [django.utils.autoreload:trigger_reload:217] /Users/welcome/Developments/repos/recommender_system_api/config/settings/dev.py changed, reloading.
INFO 07/Oct/2019 08:58:44 autoreload [django.utils.autoreload:trigger_reload:217] /Users/welcome/Developments/repos/recommender_system_api/config/settings/dev.py changed, reloading.
INFO 07/Oct/2019 08:58:46 autoreload [django.utils.autoreload:run_with_reloader:597] Watching for file changes with StatReloader
INFO 07/Oct/2019 08:58:46 autoreload [django.utils.autoreload:run_with_reloader:597] Watching for file changes with StatReloader
INFO 07/Oct/2019 09:02:48 autoreload [django.utils.autoreload:trigger_reload:217] /Users/welcome/Developments/repos/recommender_system_api/recommender_system_api/utils/connections.py changed, reloading.
INFO 07/Oct/2019 09:02:49 autoreload [django.utils.autoreload:run_with_reloader:597] Watching for file changes with StatReloader
INFO 08/Oct/2019 04:50:52 autoreload [django.utils.autoreload:run_with_reloader:597] Watching for file changes with StatReloader
WARNING 08/Oct/2019 04:51:00 log [django.request:log_response:228] Not Found: /
WARNING 08/Oct/2019 04:51:00 basehttp [django.server:log_message:154] "GET / HTTP/1.1" 404 2038
WARNING 08/Oct/2019 04:51:01 log [django.request:log_response:228] Not Found: /favicon.ico
WARNING 08/Oct/2019 04:51:01 basehttp [django.server:log_message:154] "GET /favicon.ico HTTP/1.1" 404 2089
WARNING 08/Oct/2019 04:51:13 log [django.request:log_response:228] Not Found: /recommendation/
WARNING 08/Oct/2019 04:51:13 basehttp [django.server:log_message:154] "GET /recommendation/ HTTP/1.1" 404 2427
INFO 08/Oct/2019 04:51:22 basehttp [django.server:log_message:154] "GET /recommendation/custom HTTP/1.1" 301 0
INFO 08/Oct/2019 04:51:22 basehttp [django.server:log_message:154] "GET /recommendation/custom/ HTTP/1.1" 200 748
INFO 08/Oct/2019 04:51:33 basehttp [django.server:log_message:154] "GET /recommendation/custom/ HTTP/1.1" 200 748
WARNING 08/Oct/2019 04:51:40 log [django.request:log_response:228] Not Found: /recommendation/main/
WARNING 08/Oct/2019 04:51:40 basehttp [django.server:log_message:154] "GET /recommendation/main/ HTTP/1.1" 404 2442
INFO 08/Oct/2019 04:52:20 basehttp [django.server:log_message:154] "GET /recommendation/main/15091/2 HTTP/1.1" 200 32127
WARNING 08/Oct/2019 04:52:20 log [django.request:log_response:228] Not Found: /favicon.ico
WARNING 08/Oct/2019 04:52:20 basehttp [django.server:log_message:154] "GET /favicon.ico HTTP/1.1" 404 2089
INFO 08/Oct/2019 04:52:32 basehttp [django.server:log_message:154] "GET /recommendation/main/15091/2 HTTP/1.1" 200 32127
INFO 08/Oct/2019 04:52:38 basehttp [django.server:log_message:154] "GET /recommendation/custom/ HTTP/1.1" 200 748
INFO 08/Oct/2019 04:55:16 autoreload [django.utils.autoreload:trigger_reload:217] /Users/teecoin/PycharmProjects/recommender_system_api/config/settings/base.py changed, reloading.
INFO 08/Oct/2019 04:55:17 autoreload [django.utils.autoreload:run_with_reloader:597] Watching for file changes with StatReloader
INFO 08/Oct/2019 04:55:43 autoreload [django.utils.autoreload:trigger_reload:217] /Users/teecoin/PycharmProjects/recommender_system_api/config/settings/base.py changed, reloading.
INFO 08/Oct/2019 04:55:44 autoreload [django.utils.autoreload:run_with_reloader:597] Watching for file changes with StatReloader
INFO 08/Oct/2019 05:00:02 autoreload [django.utils.autoreload:trigger_reload:217] /Users/teecoin/PycharmProjects/recommender_system_api/config/__init__.py changed, reloading.
INFO 08/Oct/2019 05:00:03 autoreload [django.utils.autoreload:run_with_reloader:597] Watching for file changes with StatReloader
INFO 08/Oct/2019 05:01:57 autoreload [django.utils.autoreload:run_with_reloader:597] Watching for file changes with StatReloader
INFO 08/Oct/2019 05:04:05 autoreload [django.utils.autoreload:trigger_reload:217] /Users/teecoin/PycharmProjects/recommender_system_api/config/__init__.py changed, reloading.
INFO 08/Oct/2019 05:04:06 autoreload [django.utils.autoreload:run_with_reloader:597] Watching for file changes with StatReloader
INFO 08/Oct/2019 05:04:51 autoreload [django.utils.autoreload:trigger_reload:217] /Users/teecoin/PycharmProjects/recommender_system_api/config/celery.py changed, reloading.
INFO 08/Oct/2019 05:04:52 autoreload [django.utils.autoreload:run_with_reloader:597] Watching for file changes with StatReloader
INFO 08/Oct/2019 05:05:37 autoreload [django.utils.autoreload:trigger_reload:217] /Users/teecoin/PycharmProjects/recommender_system_api/config/celery.py changed, reloading.
INFO 08/Oct/2019 05:05:38 autoreload [django.utils.autoreload:run_with_reloader:597] Watching for file changes with StatReloader
INFO 08/Oct/2019 06:31:56 autoreload [django.utils.autoreload:trigger_reload:217] /Users/teecoin/PycharmProjects/recommender_system_api/config/settings/__init__.py changed, reloading.
INFO 08/Oct/2019 06:32:53 autoreload [django.utils.autoreload:run_with_reloader:597] Watching for file changes with StatReloader
INFO 08/Oct/2019 06:36:24 autoreload [django.utils.autoreload:trigger_reload:217] /Users/teecoin/PycharmProjects/recommender_system_api/recommender_system_api/utils/connections.py changed, reloading.
INFO 08/Oct/2019 06:36:25 autoreload [django.utils.autoreload:run_with_reloader:597] Watching for file changes with StatReloader
INFO 08/Oct/2019 06:41:26 autoreload [django.utils.autoreload:trigger_reload:217] /Users/teecoin/PycharmProjects/recommender_system_api/config/settings/base.py changed, reloading.
INFO 08/Oct/2019 06:41:28 autoreload [django.utils.autoreload:run_with_reloader:597] Watching for file changes with StatReloader
INFO 08/Oct/2019 06:42:58 autoreload [django.utils.autoreload:trigger_reload:217] /Users/teecoin/PycharmProjects/recommender_system_api/config/settings/__init__.py changed, reloading.
INFO 08/Oct/2019 06:42:59 autoreload [django.utils.autoreload:run_with_reloader:597] Watching for file changes with StatReloader
INFO 08/Oct/2019 06:44:00 autoreload [django.utils.autoreload:trigger_reload:217] /Users/teecoin/PycharmProjects/recommender_system_api/config/celery.py changed, reloading.
INFO 08/Oct/2019 06:44:02 autoreload [django.utils.autoreload:run_with_reloader:597] Watching for file changes with StatReloader
INFO 08/Oct/2019 06:44:11 autoreload [django.utils.autoreload:trigger_reload:217] /Users/teecoin/PycharmProjects/recommender_system_api/config/celery.py changed, reloading.
INFO 08/Oct/2019 06:44:12 autoreload [django.utils.autoreload:run_with_reloader:597] Watching for file changes with StatReloader
INFO 08/Oct/2019 06:44:22 autoreload [django.utils.autoreload:trigger_reload:217] /Users/teecoin/PycharmProjects/recommender_system_api/config/settings/base.py changed, reloading.
INFO 08/Oct/2019 06:44:23 autoreload [django.utils.autoreload:run_with_reloader:597] Watching for file changes with StatReloader
INFO 08/Oct/2019 06:46:20 autoreload [django.utils.autoreload:trigger_reload:217] /Users/teecoin/PycharmProjects/recommender_system_api/config/settings/base.py changed, reloading.
INFO 08/Oct/2019 06:46:22 autoreload [django.utils.autoreload:run_with_reloader:597] Watching for file changes with StatReloader
INFO 08/Oct/2019 06:53:55 autoreload [django.utils.autoreload:trigger_reload:217] /Users/teecoin/PycharmProjects/recommender_system_api/recommender_system_api/vendors/vendor_hybrid_recommendation.py changed, reloading.
INFO 08/Oct/2019 06:53:56 autoreload [django.utils.autoreload:run_with_reloader:597] Watching for file changes with StatReloader
INFO 08/Oct/2019 07:01:11 autoreload [django.utils.autoreload:trigger_reload:217] /Users/teecoin/PycharmProjects/recommender_system_api/recommender_system_api/vendors/vendor_hybrid_recommendation.py changed, reloading.
INFO 08/Oct/2019 07:01:12 autoreload [django.utils.autoreload:run_with_reloader:597] Watching for file changes with StatReloader
INFO 08/Oct/2019 07:02:05 autoreload [django.utils.autoreload:trigger_reload:217] /Users/teecoin/PycharmProjects/recommender_system_api/recommender_system_api/api/views.py changed, reloading.
INFO 08/Oct/2019 07:02:06 autoreload [django.utils.autoreload:run_with_reloader:597] Watching for file changes with StatReloader
INFO 08/Oct/2019 07:10:29 autoreload [django.utils.autoreload:trigger_reload:217] /Users/teecoin/PycharmProjects/recommender_system_api/recommender_system_api/vendors/neural_network.py changed, reloading.
INFO 08/Oct/2019 07:10:30 autoreload [django.utils.autoreload:run_with_reloader:597] Watching for file changes with StatReloader
INFO 08/Oct/2019 07:19:49 autoreload [django.utils.autoreload:trigger_reload:217] /Users/teecoin/PycharmProjects/recommender_system_api/recommender_system_api/api/views.py changed, reloading.
INFO 08/Oct/2019 07:19:50 autoreload [django.utils.autoreload:run_with_reloader:597] Watching for file changes with StatReloader
ERROR 08/Oct/2019 07:20:07 log [django.request:log_response:228] Internal Server Error: /recommendation/main/15091/2
Traceback (most recent call last):
  File "/Users/teecoin/PycharmProjects/recommender_system_api/venv/lib/python3.6/site-packages/django/core/handlers/exception.py", line 34, in inner
    response = get_response(request)
  File "/Users/teecoin/PycharmProjects/recommender_system_api/venv/lib/python3.6/site-packages/django/core/handlers/base.py", line 115, in _get_response
    response = self.process_exception_by_middleware(e, request)
  File "/Users/teecoin/PycharmProjects/recommender_system_api/venv/lib/python3.6/site-packages/django/core/handlers/base.py", line 113, in _get_response
    response = wrapped_callback(request, *callback_args, **callback_kwargs)
  File "/Users/teecoin/PycharmProjects/recommender_system_api/venv/lib/python3.6/site-packages/django/views/decorators/csrf.py", line 54, in wrapped_view
    return view_func(*args, **kwargs)
  File "/Users/teecoin/PycharmProjects/recommender_system_api/venv/lib/python3.6/site-packages/django/views/generic/base.py", line 71, in view
    return self.dispatch(request, *args, **kwargs)
  File "/Users/teecoin/PycharmProjects/recommender_system_api/venv/lib/python3.6/site-packages/rest_framework/views.py", line 505, in dispatch
    response = self.handle_exception(exc)
  File "/Users/teecoin/PycharmProjects/recommender_system_api/venv/lib/python3.6/site-packages/rest_framework/views.py", line 465, in handle_exception
    self.raise_uncaught_exception(exc)
  File "/Users/teecoin/PycharmProjects/recommender_system_api/venv/lib/python3.6/site-packages/rest_framework/views.py", line 476, in raise_uncaught_exception
    raise exc
  File "/Users/teecoin/PycharmProjects/recommender_system_api/venv/lib/python3.6/site-packages/rest_framework/views.py", line 502, in dispatch
    response = handler(request, *args, **kwargs)
  File "/Users/teecoin/PycharmProjects/recommender_system_api/venv/lib/python3.6/site-packages/rest_framework/decorators.py", line 50, in handler
    return func(*args, **kwargs)
  File "/Users/teecoin/PycharmProjects/recommender_system_api/recommender_system_api/api/views.py", line 27, in get_main_page_recommendations
    vendor_cosine_sim, neural_net_model, new_user, has_reviewed)
  File "/Users/teecoin/PycharmProjects/recommender_system_api/recommender_system_api/vendors/vendor_hybrid_recommendation.py", line 48, in main_page_recommendation
    vendor_recommendation_nn = build_user_profile_nn(user_id, gender, model=neural_net_model, rating_df=rating_df)
  File "/Users/teecoin/PycharmProjects/recommender_system_api/recommender_system_api/vendors/user_profiles.py", line 16, in build_user_profile_nn
    user_id = rating_df[rating_df.user_id == user_id].user_id.iloc[0]
  File "/Users/teecoin/PycharmProjects/recommender_system_api/venv/lib/python3.6/site-packages/pandas/core/indexing.py", line 1424, in __getitem__
    return self._getitem_axis(maybe_callable, axis=axis)
  File "/Users/teecoin/PycharmProjects/recommender_system_api/venv/lib/python3.6/site-packages/pandas/core/indexing.py", line 2157, in _getitem_axis
    self._validate_integer(key, axis)
  File "/Users/teecoin/PycharmProjects/recommender_system_api/venv/lib/python3.6/site-packages/pandas/core/indexing.py", line 2088, in _validate_integer
    raise IndexError("single positional indexer is out-of-bounds")
IndexError: single positional indexer is out-of-bounds
ERROR 08/Oct/2019 07:20:07 basehttp [django.server:log_message:154] "GET /recommendation/main/15091/2 HTTP/1.1" 500 19722
INFO 08/Oct/2019 07:20:18 autoreload [django.utils.autoreload:run_with_reloader:597] Watching for file changes with StatReloader
ERROR 08/Oct/2019 07:20:24 log [django.request:log_response:228] Internal Server Error: /recommendation/main/15091/2
Traceback (most recent call last):
  File "/Users/teecoin/PycharmProjects/recommender_system_api/venv/lib/python3.6/site-packages/django/core/handlers/exception.py", line 34, in inner
    response = get_response(request)
  File "/Users/teecoin/PycharmProjects/recommender_system_api/venv/lib/python3.6/site-packages/django/core/handlers/base.py", line 115, in _get_response
    response = self.process_exception_by_middleware(e, request)
  File "/Users/teecoin/PycharmProjects/recommender_system_api/venv/lib/python3.6/site-packages/django/core/handlers/base.py", line 113, in _get_response
    response = wrapped_callback(request, *callback_args, **callback_kwargs)
  File "/Users/teecoin/PycharmProjects/recommender_system_api/venv/lib/python3.6/site-packages/django/views/decorators/csrf.py", line 54, in wrapped_view
    return view_func(*args, **kwargs)
  File "/Users/teecoin/PycharmProjects/recommender_system_api/venv/lib/python3.6/site-packages/django/views/generic/base.py", line 71, in view
    return self.dispatch(request, *args, **kwargs)
  File "/Users/teecoin/PycharmProjects/recommender_system_api/venv/lib/python3.6/site-packages/rest_framework/views.py", line 505, in dispatch
    response = self.handle_exception(exc)
  File "/Users/teecoin/PycharmProjects/recommender_system_api/venv/lib/python3.6/site-packages/rest_framework/views.py", line 465, in handle_exception
    self.raise_uncaught_exception(exc)
  File "/Users/teecoin/PycharmProjects/recommender_system_api/venv/lib/python3.6/site-packages/rest_framework/views.py", line 476, in raise_uncaught_exception
    raise exc
  File "/Users/teecoin/PycharmProjects/recommender_system_api/venv/lib/python3.6/site-packages/rest_framework/views.py", line 502, in dispatch
    response = handler(request, *args, **kwargs)
  File "/Users/teecoin/PycharmProjects/recommender_system_api/venv/lib/python3.6/site-packages/rest_framework/decorators.py", line 50, in handler
    return func(*args, **kwargs)
  File "/Users/teecoin/PycharmProjects/recommender_system_api/recommender_system_api/api/views.py", line 27, in get_main_page_recommendations
    vendor_cosine_sim, neural_net_model, new_user, has_reviewed)
  File "/Users/teecoin/PycharmProjects/recommender_system_api/recommender_system_api/vendors/vendor_hybrid_recommendation.py", line 48, in main_page_recommendation
    vendor_recommendation_nn = build_user_profile_nn(user_id, gender, model=neural_net_model, rating_df=rating_df)
  File "/Users/teecoin/PycharmProjects/recommender_system_api/recommender_system_api/vendors/user_profiles.py", line 16, in build_user_profile_nn
    user_id = rating_df[rating_df.user_id == user_id].user_id.iloc[0]
  File "/Users/teecoin/PycharmProjects/recommender_system_api/venv/lib/python3.6/site-packages/pandas/core/indexing.py", line 1424, in __getitem__
    return self._getitem_axis(maybe_callable, axis=axis)
  File "/Users/teecoin/PycharmProjects/recommender_system_api/venv/lib/python3.6/site-packages/pandas/core/indexing.py", line 2157, in _getitem_axis
    self._validate_integer(key, axis)
  File "/Users/teecoin/PycharmProjects/recommender_system_api/venv/lib/python3.6/site-packages/pandas/core/indexing.py", line 2088, in _validate_integer
    raise IndexError("single positional indexer is out-of-bounds")
IndexError: single positional indexer is out-of-bounds
ERROR 08/Oct/2019 07:20:24 basehttp [django.server:log_message:154] "GET /recommendation/main/15091/2 HTTP/1.1" 500 19755
ERROR 08/Oct/2019 07:20:47 log [django.request:log_response:228] Internal Server Error: /recommendation/custom/
Traceback (most recent call last):
  File "/Users/teecoin/PycharmProjects/recommender_system_api/venv/lib/python3.6/site-packages/django/core/handlers/exception.py", line 34, in inner
    response = get_response(request)
  File "/Users/teecoin/PycharmProjects/recommender_system_api/venv/lib/python3.6/site-packages/django/core/handlers/base.py", line 115, in _get_response
    response = self.process_exception_by_middleware(e, request)
  File "/Users/teecoin/PycharmProjects/recommender_system_api/venv/lib/python3.6/site-packages/django/core/handlers/base.py", line 113, in _get_response
    response = wrapped_callback(request, *callback_args, **callback_kwargs)
  File "/Users/teecoin/PycharmProjects/recommender_system_api/venv/lib/python3.6/site-packages/django/views/decorators/csrf.py", line 54, in wrapped_view
    return view_func(*args, **kwargs)
  File "/Users/teecoin/PycharmProjects/recommender_system_api/venv/lib/python3.6/site-packages/django/views/generic/base.py", line 71, in view
    return self.dispatch(request, *args, **kwargs)
  File "/Users/teecoin/PycharmProjects/recommender_system_api/venv/lib/python3.6/site-packages/rest_framework/views.py", line 505, in dispatch
    response = self.handle_exception(exc)
  File "/Users/teecoin/PycharmProjects/recommender_system_api/venv/lib/python3.6/site-packages/rest_framework/views.py", line 465, in handle_exception
    self.raise_uncaught_exception(exc)
  File "/Users/teecoin/PycharmProjects/recommender_system_api/venv/lib/python3.6/site-packages/rest_framework/views.py", line 476, in raise_uncaught_exception
    raise exc
  File "/Users/teecoin/PycharmProjects/recommender_system_api/venv/lib/python3.6/site-packages/rest_framework/views.py", line 502, in dispatch
    response = handler(request, *args, **kwargs)
  File "/Users/teecoin/PycharmProjects/recommender_system_api/venv/lib/python3.6/site-packages/rest_framework/decorators.py", line 50, in handler
    return func(*args, **kwargs)
  File "/Users/teecoin/PycharmProjects/recommender_system_api/recommender_system_api/api/views.py", line 44, in get_custom_page_recommendations
    vendor_id_arr, rating_df, vendor_cosine_sim, neural_net_model)
  File "/Users/teecoin/PycharmProjects/recommender_system_api/recommender_system_api/vendors/vendor_hybrid_recommendation.py", line 79, in specific_recommendation
    rating_df=rating_df, vendor_id=vendor_id)
  File "/Users/teecoin/PycharmProjects/recommender_system_api/recommender_system_api/vendors/user_profiles.py", line 39, in build_user_profile_cb
    idx = indices[indices == vendor_id].index[0]
  File "/Users/teecoin/PycharmProjects/recommender_system_api/venv/lib/python3.6/site-packages/pandas/core/indexes/base.py", line 4280, in __getitem__
    return getitem(key)
IndexError: index 0 is out of bounds for axis 0 with size 0
ERROR 08/Oct/2019 07:20:47 basehttp [django.server:log_message:154] "GET /recommendation/custom/ HTTP/1.1" 500 19258
INFO 08/Oct/2019 08:15:25 autoreload [django.utils.autoreload:run_with_reloader:597] Watching for file changes with StatReloader
INFO 08/Oct/2019 08:27:06 autoreload [django.utils.autoreload:run_with_reloader:597] Watching for file changes with StatReloader
INFO 08/Oct/2019 08:28:18 autoreload [django.utils.autoreload:run_with_reloader:597] Watching for file changes with StatReloader
INFO 08/Oct/2019 08:34:15 autoreload [django.utils.autoreload:trigger_reload:217] /Users/teecoin/PycharmProjects/recommender_system_api/recommender_system_api/vendors/neural_network.py changed, reloading.
INFO 08/Oct/2019 08:34:15 autoreload [django.utils.autoreload:trigger_reload:217] /Users/teecoin/PycharmProjects/recommender_system_api/recommender_system_api/vendors/neural_network.py changed, reloading.
INFO 08/Oct/2019 08:34:17 autoreload [django.utils.autoreload:run_with_reloader:597] Watching for file changes with StatReloader
INFO 08/Oct/2019 08:34:17 autoreload [django.utils.autoreload:run_with_reloader:597] Watching for file changes with StatReloader
ERROR 08/Oct/2019 08:36:15 log [django.request:log_response:228] Internal Server Error: /recommendation/custom/
Traceback (most recent call last):
  File "/Users/teecoin/PycharmProjects/recommender_system_api/venv/lib/python3.6/site-packages/django/core/handlers/exception.py", line 34, in inner
    response = get_response(request)
  File "/Users/teecoin/PycharmProjects/recommender_system_api/venv/lib/python3.6/site-packages/django/core/handlers/base.py", line 115, in _get_response
    response = self.process_exception_by_middleware(e, request)
  File "/Users/teecoin/PycharmProjects/recommender_system_api/venv/lib/python3.6/site-packages/django/core/handlers/base.py", line 113, in _get_response
    response = wrapped_callback(request, *callback_args, **callback_kwargs)
  File "/Users/teecoin/PycharmProjects/recommender_system_api/venv/lib/python3.6/site-packages/django/views/decorators/csrf.py", line 54, in wrapped_view
    return view_func(*args, **kwargs)
  File "/Users/teecoin/PycharmProjects/recommender_system_api/venv/lib/python3.6/site-packages/django/views/generic/base.py", line 71, in view
    return self.dispatch(request, *args, **kwargs)
  File "/Users/teecoin/PycharmProjects/recommender_system_api/venv/lib/python3.6/site-packages/rest_framework/views.py", line 505, in dispatch
    response = self.handle_exception(exc)
  File "/Users/teecoin/PycharmProjects/recommender_system_api/venv/lib/python3.6/site-packages/rest_framework/views.py", line 465, in handle_exception
    self.raise_uncaught_exception(exc)
  File "/Users/teecoin/PycharmProjects/recommender_system_api/venv/lib/python3.6/site-packages/rest_framework/views.py", line 476, in raise_uncaught_exception
    raise exc
  File "/Users/teecoin/PycharmProjects/recommender_system_api/venv/lib/python3.6/site-packages/rest_framework/views.py", line 502, in dispatch
    response = handler(request, *args, **kwargs)
  File "/Users/teecoin/PycharmProjects/recommender_system_api/venv/lib/python3.6/site-packages/rest_framework/decorators.py", line 50, in handler
    return func(*args, **kwargs)
  File "/Users/teecoin/PycharmProjects/recommender_system_api/recommender_system_api/api/views.py", line 44, in get_custom_page_recommendations
    vendor_id_arr, rating_df, vendor_cosine_sim, neural_net_model)
NameError: name 'vendor_id_arr' is not defined
ERROR 08/Oct/2019 08:36:15 basehttp [django.server:log_message:154] "GET /recommendation/custom/ HTTP/1.1" 500 18613
ERROR 08/Oct/2019 08:36:53 log [django.request:log_response:228] Internal Server Error: /recommendation/main/15091/2
Traceback (most recent call last):
  File "/Users/teecoin/PycharmProjects/recommender_system_api/venv/lib/python3.6/site-packages/django/core/handlers/exception.py", line 34, in inner
    response = get_response(request)
  File "/Users/teecoin/PycharmProjects/recommender_system_api/venv/lib/python3.6/site-packages/django/core/handlers/base.py", line 115, in _get_response
    response = self.process_exception_by_middleware(e, request)
  File "/Users/teecoin/PycharmProjects/recommender_system_api/venv/lib/python3.6/site-packages/django/core/handlers/base.py", line 113, in _get_response
    response = wrapped_callback(request, *callback_args, **callback_kwargs)
  File "/Users/teecoin/PycharmProjects/recommender_system_api/venv/lib/python3.6/site-packages/django/views/decorators/csrf.py", line 54, in wrapped_view
    return view_func(*args, **kwargs)
  File "/Users/teecoin/PycharmProjects/recommender_system_api/venv/lib/python3.6/site-packages/django/views/generic/base.py", line 71, in view
    return self.dispatch(request, *args, **kwargs)
  File "/Users/teecoin/PycharmProjects/recommender_system_api/venv/lib/python3.6/site-packages/rest_framework/views.py", line 505, in dispatch
    response = self.handle_exception(exc)
  File "/Users/teecoin/PycharmProjects/recommender_system_api/venv/lib/python3.6/site-packages/rest_framework/views.py", line 465, in handle_exception
    self.raise_uncaught_exception(exc)
  File "/Users/teecoin/PycharmProjects/recommender_system_api/venv/lib/python3.6/site-packages/rest_framework/views.py", line 476, in raise_uncaught_exception
    raise exc
  File "/Users/teecoin/PycharmProjects/recommender_system_api/venv/lib/python3.6/site-packages/rest_framework/views.py", line 502, in dispatch
    response = handler(request, *args, **kwargs)
  File "/Users/teecoin/PycharmProjects/recommender_system_api/venv/lib/python3.6/site-packages/rest_framework/decorators.py", line 50, in handler
    return func(*args, **kwargs)
  File "/Users/teecoin/PycharmProjects/recommender_system_api/recommender_system_api/api/views.py", line 26, in get_main_page_recommendations
    recommendation = main_page_recommendation(user_id, gender, vendor_id_arr, rating_df,
NameError: name 'vendor_id_arr' is not defined
ERROR 08/Oct/2019 08:36:53 basehttp [django.server:log_message:154] "GET /recommendation/main/15091/2 HTTP/1.1" 500 18579
INFO 08/Oct/2019 08:40:18 autoreload [django.utils.autoreload:run_with_reloader:597] Watching for file changes with StatReloader
INFO 08/Oct/2019 08:42:58 autoreload [django.utils.autoreload:trigger_reload:217] /Users/teecoin/PycharmProjects/recommender_system_api/config/settings/base.py changed, reloading.
INFO 08/Oct/2019 08:43:00 autoreload [django.utils.autoreload:run_with_reloader:597] Watching for file changes with StatReloader
INFO 08/Oct/2019 08:43:07 autoreload [django.utils.autoreload:trigger_reload:217] /Users/teecoin/PycharmProjects/recommender_system_api/config/settings/base.py changed, reloading.
INFO 08/Oct/2019 08:43:08 autoreload [django.utils.autoreload:run_with_reloader:597] Watching for file changes with StatReloader
INFO 08/Oct/2019 08:43:15 autoreload [django.utils.autoreload:trigger_reload:217] /Users/teecoin/PycharmProjects/recommender_system_api/config/settings/base.py changed, reloading.
INFO 08/Oct/2019 08:43:16 autoreload [django.utils.autoreload:run_with_reloader:597] Watching for file changes with StatReloader
INFO 08/Oct/2019 08:48:45 autoreload [django.utils.autoreload:run_with_reloader:597] Watching for file changes with StatReloader
INFO 08/Oct/2019 08:55:19 autoreload [django.utils.autoreload:trigger_reload:217] /Users/teecoin/PycharmProjects/recommender_system_api/recommender_system_api/vendors/neural_network.py changed, reloading.
INFO 08/Oct/2019 08:55:19 autoreload [django.utils.autoreload:trigger_reload:217] /Users/teecoin/PycharmProjects/recommender_system_api/recommender_system_api/vendors/neural_network.py changed, reloading.
INFO 08/Oct/2019 08:55:20 autoreload [django.utils.autoreload:run_with_reloader:597] Watching for file changes with StatReloader
INFO 08/Oct/2019 08:55:20 autoreload [django.utils.autoreload:run_with_reloader:597] Watching for file changes with StatReloader
INFO 08/Oct/2019 08:56:30 autoreload [django.utils.autoreload:trigger_reload:217] /Users/teecoin/PycharmProjects/recommender_system_api/config/settings/base.py changed, reloading.
INFO 08/Oct/2019 08:56:30 autoreload [django.utils.autoreload:trigger_reload:217] /Users/teecoin/PycharmProjects/recommender_system_api/config/settings/base.py changed, reloading.
INFO 08/Oct/2019 08:56:31 autoreload [django.utils.autoreload:run_with_reloader:597] Watching for file changes with StatReloader
INFO 08/Oct/2019 08:56:31 autoreload [django.utils.autoreload:run_with_reloader:597] Watching for file changes with StatReloader
INFO 08/Oct/2019 08:57:56 autoreload [django.utils.autoreload:run_with_reloader:597] Watching for file changes with StatReloader
INFO 08/Oct/2019 08:58:24 autoreload [django.utils.autoreload:trigger_reload:217] /Users/teecoin/PycharmProjects/recommender_system_api/config/settings/base.py changed, reloading.
INFO 08/Oct/2019 08:58:24 autoreload [django.utils.autoreload:trigger_reload:217] /Users/teecoin/PycharmProjects/recommender_system_api/config/settings/base.py changed, reloading.
INFO 08/Oct/2019 08:58:25 autoreload [django.utils.autoreload:run_with_reloader:597] Watching for file changes with StatReloader
INFO 08/Oct/2019 08:58:25 autoreload [django.utils.autoreload:run_with_reloader:597] Watching for file changes with StatReloader
ERROR 08/Oct/2019 08:58:40 log [django.request:log_response:228] Internal Server Error: /recommendation/custom/
Traceback (most recent call last):
  File "/Users/teecoin/PycharmProjects/recommender_system_api/venv/lib/python3.6/site-packages/django/core/handlers/exception.py", line 34, in inner
    response = get_response(request)
  File "/Users/teecoin/PycharmProjects/recommender_system_api/venv/lib/python3.6/site-packages/django/core/handlers/base.py", line 115, in _get_response
    response = self.process_exception_by_middleware(e, request)
  File "/Users/teecoin/PycharmProjects/recommender_system_api/venv/lib/python3.6/site-packages/django/core/handlers/base.py", line 113, in _get_response
    response = wrapped_callback(request, *callback_args, **callback_kwargs)
  File "/Users/teecoin/PycharmProjects/recommender_system_api/venv/lib/python3.6/site-packages/django/views/decorators/csrf.py", line 54, in wrapped_view
    return view_func(*args, **kwargs)
  File "/Users/teecoin/PycharmProjects/recommender_system_api/venv/lib/python3.6/site-packages/django/views/generic/base.py", line 71, in view
    return self.dispatch(request, *args, **kwargs)
  File "/Users/teecoin/PycharmProjects/recommender_system_api/venv/lib/python3.6/site-packages/rest_framework/views.py", line 505, in dispatch
    response = self.handle_exception(exc)
  File "/Users/teecoin/PycharmProjects/recommender_system_api/venv/lib/python3.6/site-packages/rest_framework/views.py", line 465, in handle_exception
    self.raise_uncaught_exception(exc)
  File "/Users/teecoin/PycharmProjects/recommender_system_api/venv/lib/python3.6/site-packages/rest_framework/views.py", line 476, in raise_uncaught_exception
    raise exc
  File "/Users/teecoin/PycharmProjects/recommender_system_api/venv/lib/python3.6/site-packages/rest_framework/views.py", line 502, in dispatch
    response = handler(request, *args, **kwargs)
  File "/Users/teecoin/PycharmProjects/recommender_system_api/venv/lib/python3.6/site-packages/rest_framework/decorators.py", line 50, in handler
    return func(*args, **kwargs)
  File "/Users/teecoin/PycharmProjects/recommender_system_api/recommender_system_api/api/views.py", line 44, in get_custom_page_recommendations
    vendor_id_arr, rating_df, vendor_cosine_sim, neural_net_model)
NameError: name 'vendor_id_arr' is not defined
ERROR 08/Oct/2019 08:58:40 basehttp [django.server:log_message:154] "GET /recommendation/custom/ HTTP/1.1" 500 18644
ERROR 08/Oct/2019 08:59:10 log [django.request:log_response:228] Internal Server Error: /recommendation/custom/
Traceback (most recent call last):
  File "/Users/teecoin/PycharmProjects/recommender_system_api/venv/lib/python3.6/site-packages/django/core/handlers/exception.py", line 34, in inner
    response = get_response(request)
  File "/Users/teecoin/PycharmProjects/recommender_system_api/venv/lib/python3.6/site-packages/django/core/handlers/base.py", line 115, in _get_response
    response = self.process_exception_by_middleware(e, request)
  File "/Users/teecoin/PycharmProjects/recommender_system_api/venv/lib/python3.6/site-packages/django/core/handlers/base.py", line 113, in _get_response
    response = wrapped_callback(request, *callback_args, **callback_kwargs)
  File "/Users/teecoin/PycharmProjects/recommender_system_api/venv/lib/python3.6/site-packages/django/views/decorators/csrf.py", line 54, in wrapped_view
    return view_func(*args, **kwargs)
  File "/Users/teecoin/PycharmProjects/recommender_system_api/venv/lib/python3.6/site-packages/django/views/generic/base.py", line 71, in view
    return self.dispatch(request, *args, **kwargs)
  File "/Users/teecoin/PycharmProjects/recommender_system_api/venv/lib/python3.6/site-packages/rest_framework/views.py", line 505, in dispatch
    response = self.handle_exception(exc)
  File "/Users/teecoin/PycharmProjects/recommender_system_api/venv/lib/python3.6/site-packages/rest_framework/views.py", line 465, in handle_exception
    self.raise_uncaught_exception(exc)
  File "/Users/teecoin/PycharmProjects/recommender_system_api/venv/lib/python3.6/site-packages/rest_framework/views.py", line 476, in raise_uncaught_exception
    raise exc
  File "/Users/teecoin/PycharmProjects/recommender_system_api/venv/lib/python3.6/site-packages/rest_framework/views.py", line 502, in dispatch
    response = handler(request, *args, **kwargs)
  File "/Users/teecoin/PycharmProjects/recommender_system_api/venv/lib/python3.6/site-packages/rest_framework/decorators.py", line 50, in handler
    return func(*args, **kwargs)
  File "/Users/teecoin/PycharmProjects/recommender_system_api/recommender_system_api/api/views.py", line 44, in get_custom_page_recommendations
    vendor_id_arr, rating_df, vendor_cosine_sim, neural_net_model)
NameError: name 'vendor_id_arr' is not defined
ERROR 08/Oct/2019 08:59:10 basehttp [django.server:log_message:154] "GET /recommendation/custom/ HTTP/1.1" 500 18651
INFO 08/Oct/2019 09:04:00 autoreload [django.utils.autoreload:trigger_reload:217] /Users/teecoin/PycharmProjects/recommender_system_api/recommender_system_api/api/views.py changed, reloading.
INFO 08/Oct/2019 09:04:00 autoreload [django.utils.autoreload:trigger_reload:217] /Users/teecoin/PycharmProjects/recommender_system_api/recommender_system_api/api/views.py changed, reloading.
INFO 08/Oct/2019 09:04:01 autoreload [django.utils.autoreload:run_with_reloader:597] Watching for file changes with StatReloader
INFO 08/Oct/2019 09:04:01 autoreload [django.utils.autoreload:run_with_reloader:597] Watching for file changes with StatReloader
INFO 08/Oct/2019 11:35:36 autoreload [django.utils.autoreload:run_with_reloader:597] Watching for file changes with StatReloader
INFO 08/Oct/2019 11:37:59 autoreload [django.utils.autoreload:trigger_reload:217] /Users/teecoin/PycharmProjects/recommender_system_api/recommender_system_api/api/views.py changed, reloading.
INFO 08/Oct/2019 11:38:01 autoreload [django.utils.autoreload:run_with_reloader:597] Watching for file changes with StatReloader
INFO 08/Oct/2019 11:46:07 autoreload [django.utils.autoreload:trigger_reload:217] /Users/teecoin/PycharmProjects/recommender_system_api/recommender_system_api/api/views.py changed, reloading.
INFO 08/Oct/2019 11:46:09 autoreload [django.utils.autoreload:run_with_reloader:597] Watching for file changes with StatReloader
INFO 08/Oct/2019 11:49:36 autoreload [django.utils.autoreload:trigger_reload:217] /Users/teecoin/PycharmProjects/recommender_system_api/recommender_system_api/api/views.py changed, reloading.
INFO 08/Oct/2019 11:49:37 autoreload [django.utils.autoreload:run_with_reloader:597] Watching for file changes with StatReloader
INFO 08/Oct/2019 11:49:48 autoreload [django.utils.autoreload:trigger_reload:217] /Users/teecoin/PycharmProjects/recommender_system_api/recommender_system_api/api/views.py changed, reloading.
INFO 08/Oct/2019 11:49:49 autoreload [django.utils.autoreload:run_with_reloader:597] Watching for file changes with StatReloader
INFO 08/Oct/2019 11:51:21 autoreload [django.utils.autoreload:trigger_reload:217] /Users/teecoin/PycharmProjects/recommender_system_api/recommender_system_api/api/views.py changed, reloading.
INFO 08/Oct/2019 11:51:22 autoreload [django.utils.autoreload:run_with_reloader:597] Watching for file changes with StatReloader
INFO 08/Oct/2019 11:53:53 autoreload [django.utils.autoreload:trigger_reload:217] /Users/teecoin/PycharmProjects/recommender_system_api/recommender_system_api/api/views.py changed, reloading.
INFO 08/Oct/2019 11:53:54 autoreload [django.utils.autoreload:run_with_reloader:597] Watching for file changes with StatReloader
INFO 08/Oct/2019 11:54:48 autoreload [django.utils.autoreload:trigger_reload:217] /Users/teecoin/PycharmProjects/recommender_system_api/config/settings/base.py changed, reloading.
INFO 08/Oct/2019 11:54:48 autoreload [django.utils.autoreload:trigger_reload:217] /Users/teecoin/PycharmProjects/recommender_system_api/config/settings/base.py changed, reloading.
INFO 08/Oct/2019 11:54:49 autoreload [django.utils.autoreload:run_with_reloader:597] Watching for file changes with StatReloader
INFO 08/Oct/2019 11:54:49 autoreload [django.utils.autoreload:run_with_reloader:597] Watching for file changes with StatReloader
INFO 08/Oct/2019 11:55:27 autoreload [django.utils.autoreload:run_with_reloader:597] Watching for file changes with StatReloader
INFO 08/Oct/2019 11:55:49 autoreload [django.utils.autoreload:trigger_reload:217] /Users/teecoin/PycharmProjects/recommender_system_api/recommender_system_api/api/tasks.py changed, reloading.
INFO 08/Oct/2019 11:55:49 autoreload [django.utils.autoreload:trigger_reload:217] /Users/teecoin/PycharmProjects/recommender_system_api/recommender_system_api/api/tasks.py changed, reloading.
INFO 08/Oct/2019 11:55:50 autoreload [django.utils.autoreload:run_with_reloader:597] Watching for file changes with StatReloader
INFO 08/Oct/2019 11:55:50 autoreload [django.utils.autoreload:run_with_reloader:597] Watching for file changes with StatReloader
INFO 08/Oct/2019 11:56:46 autoreload [django.utils.autoreload:run_with_reloader:597] Watching for file changes with StatReloader
INFO 08/Oct/2019 11:57:12 autoreload [django.utils.autoreload:trigger_reload:217] /Users/teecoin/PycharmProjects/recommender_system_api/recommender_system_api/api/tasks.py changed, reloading.
INFO 08/Oct/2019 11:57:13 autoreload [django.utils.autoreload:trigger_reload:217] /Users/teecoin/PycharmProjects/recommender_system_api/recommender_system_api/api/tasks.py changed, reloading.
INFO 08/Oct/2019 11:57:14 autoreload [django.utils.autoreload:run_with_reloader:597] Watching for file changes with StatReloader
INFO 08/Oct/2019 11:57:14 autoreload [django.utils.autoreload:run_with_reloader:597] Watching for file changes with StatReloader
INFO 08/Oct/2019 11:58:12 autoreload [django.utils.autoreload:trigger_reload:217] /Users/teecoin/PycharmProjects/recommender_system_api/recommender_system_api/api/tasks.py changed, reloading.
INFO 08/Oct/2019 11:58:12 autoreload [django.utils.autoreload:trigger_reload:217] /Users/teecoin/PycharmProjects/recommender_system_api/recommender_system_api/api/tasks.py changed, reloading.
INFO 08/Oct/2019 11:58:13 autoreload [django.utils.autoreload:run_with_reloader:597] Watching for file changes with StatReloader
INFO 08/Oct/2019 11:58:13 autoreload [django.utils.autoreload:run_with_reloader:597] Watching for file changes with StatReloader
INFO 08/Oct/2019 11:58:24 autoreload [django.utils.autoreload:trigger_reload:217] /Users/teecoin/PycharmProjects/recommender_system_api/recommender_system_api/api/tasks.py changed, reloading.
INFO 08/Oct/2019 11:58:24 autoreload [django.utils.autoreload:trigger_reload:217] /Users/teecoin/PycharmProjects/recommender_system_api/recommender_system_api/api/tasks.py changed, reloading.
INFO 08/Oct/2019 11:58:25 autoreload [django.utils.autoreload:run_with_reloader:597] Watching for file changes with StatReloader
INFO 08/Oct/2019 11:58:26 autoreload [django.utils.autoreload:run_with_reloader:597] Watching for file changes with StatReloader
INFO 08/Oct/2019 11:59:23 autoreload [django.utils.autoreload:run_with_reloader:597] Watching for file changes with StatReloader
INFO 08/Oct/2019 12:00:15 autoreload [django.utils.autoreload:trigger_reload:217] /Users/teecoin/PycharmProjects/recommender_system_api/recommender_system_api/api/tasks.py changed, reloading.
INFO 08/Oct/2019 12:00:15 autoreload [django.utils.autoreload:trigger_reload:217] /Users/teecoin/PycharmProjects/recommender_system_api/recommender_system_api/api/tasks.py changed, reloading.
INFO 08/Oct/2019 12:00:16 autoreload [django.utils.autoreload:run_with_reloader:597] Watching for file changes with StatReloader
INFO 08/Oct/2019 12:00:17 autoreload [django.utils.autoreload:run_with_reloader:597] Watching for file changes with StatReloader
INFO 08/Oct/2019 12:00:52 autoreload [django.utils.autoreload:trigger_reload:217] /Users/teecoin/PycharmProjects/recommender_system_api/config/settings/base.py changed, reloading.
INFO 08/Oct/2019 12:00:52 autoreload [django.utils.autoreload:trigger_reload:217] /Users/teecoin/PycharmProjects/recommender_system_api/config/settings/base.py changed, reloading.
INFO 08/Oct/2019 12:00:53 autoreload [django.utils.autoreload:run_with_reloader:597] Watching for file changes with StatReloader
INFO 08/Oct/2019 12:00:53 autoreload [django.utils.autoreload:run_with_reloader:597] Watching for file changes with StatReloader
INFO 09/Oct/2019 10:40:35 autoreload [django.utils.autoreload:run_with_reloader:597] Watching for file changes with StatReloader
ERROR 09/Oct/2019 10:42:39 log [django.request:log_response:228] Internal Server Error: /recommendation/custom/
Traceback (most recent call last):
  File "/Users/teecoin/PycharmProjects/recommender_system_api/venv/lib/python3.6/site-packages/django/core/handlers/exception.py", line 34, in inner
    response = get_response(request)
  File "/Users/teecoin/PycharmProjects/recommender_system_api/venv/lib/python3.6/site-packages/django/core/handlers/base.py", line 115, in _get_response
    response = self.process_exception_by_middleware(e, request)
  File "/Users/teecoin/PycharmProjects/recommender_system_api/venv/lib/python3.6/site-packages/django/core/handlers/base.py", line 113, in _get_response
    response = wrapped_callback(request, *callback_args, **callback_kwargs)
  File "/Users/teecoin/PycharmProjects/recommender_system_api/venv/lib/python3.6/site-packages/django/views/decorators/csrf.py", line 54, in wrapped_view
    return view_func(*args, **kwargs)
  File "/Users/teecoin/PycharmProjects/recommender_system_api/venv/lib/python3.6/site-packages/django/views/generic/base.py", line 71, in view
    return self.dispatch(request, *args, **kwargs)
  File "/Users/teecoin/PycharmProjects/recommender_system_api/venv/lib/python3.6/site-packages/rest_framework/views.py", line 505, in dispatch
    response = self.handle_exception(exc)
  File "/Users/teecoin/PycharmProjects/recommender_system_api/venv/lib/python3.6/site-packages/rest_framework/views.py", line 465, in handle_exception
    self.raise_uncaught_exception(exc)
  File "/Users/teecoin/PycharmProjects/recommender_system_api/venv/lib/python3.6/site-packages/rest_framework/views.py", line 476, in raise_uncaught_exception
    raise exc
  File "/Users/teecoin/PycharmProjects/recommender_system_api/venv/lib/python3.6/site-packages/rest_framework/views.py", line 502, in dispatch
    response = handler(request, *args, **kwargs)
  File "/Users/teecoin/PycharmProjects/recommender_system_api/venv/lib/python3.6/site-packages/rest_framework/decorators.py", line 50, in handler
    return func(*args, **kwargs)
  File "/Users/teecoin/PycharmProjects/recommender_system_api/recommender_system_api/api/views.py", line 44, in get_custom_page_recommendations
    vendor_id_arr, rating_df, vendor_cosine_sim, neural_net_model)
  File "/Users/teecoin/PycharmProjects/recommender_system_api/recommender_system_api/vendors/vendor_hybrid_recommendation.py", line 79, in specific_recommendation
    rating_df=rating_df, vendor_id=vendor_id)
  File "/Users/teecoin/PycharmProjects/recommender_system_api/recommender_system_api/vendors/user_profiles.py", line 39, in build_user_profile_cb
    idx = indices[indices == vendor_id].index[0]
  File "/Users/teecoin/PycharmProjects/recommender_system_api/venv/lib/python3.6/site-packages/pandas/core/indexes/base.py", line 4280, in __getitem__
    return getitem(key)
IndexError: index 0 is out of bounds for axis 0 with size 0
ERROR 09/Oct/2019 10:42:39 basehttp [django.server:log_message:154] "GET /recommendation/custom/ HTTP/1.1" 500 19296
WARNING 09/Oct/2019 10:42:40 log [django.request:log_response:228] Not Found: /favicon.ico
WARNING 09/Oct/2019 10:42:40 basehttp [django.server:log_message:154] "GET /favicon.ico HTTP/1.1" 404 2089
INFO 09/Oct/2019 10:43:16 basehttp [django.server:log_message:154] "GET /recommendation/custom HTTP/1.1" 301 0
ERROR 09/Oct/2019 10:43:16 log [django.request:log_response:228] Internal Server Error: /recommendation/custom/
Traceback (most recent call last):
  File "/Users/teecoin/PycharmProjects/recommender_system_api/venv/lib/python3.6/site-packages/django/core/handlers/exception.py", line 34, in inner
    response = get_response(request)
  File "/Users/teecoin/PycharmProjects/recommender_system_api/venv/lib/python3.6/site-packages/django/core/handlers/base.py", line 115, in _get_response
    response = self.process_exception_by_middleware(e, request)
  File "/Users/teecoin/PycharmProjects/recommender_system_api/venv/lib/python3.6/site-packages/django/core/handlers/base.py", line 113, in _get_response
    response = wrapped_callback(request, *callback_args, **callback_kwargs)
  File "/Users/teecoin/PycharmProjects/recommender_system_api/venv/lib/python3.6/site-packages/django/views/decorators/csrf.py", line 54, in wrapped_view
    return view_func(*args, **kwargs)
  File "/Users/teecoin/PycharmProjects/recommender_system_api/venv/lib/python3.6/site-packages/django/views/generic/base.py", line 71, in view
    return self.dispatch(request, *args, **kwargs)
  File "/Users/teecoin/PycharmProjects/recommender_system_api/venv/lib/python3.6/site-packages/rest_framework/views.py", line 505, in dispatch
    response = self.handle_exception(exc)
  File "/Users/teecoin/PycharmProjects/recommender_system_api/venv/lib/python3.6/site-packages/rest_framework/views.py", line 465, in handle_exception
    self.raise_uncaught_exception(exc)
  File "/Users/teecoin/PycharmProjects/recommender_system_api/venv/lib/python3.6/site-packages/rest_framework/views.py", line 476, in raise_uncaught_exception
    raise exc
  File "/Users/teecoin/PycharmProjects/recommender_system_api/venv/lib/python3.6/site-packages/rest_framework/views.py", line 502, in dispatch
    response = handler(request, *args, **kwargs)
  File "/Users/teecoin/PycharmProjects/recommender_system_api/venv/lib/python3.6/site-packages/rest_framework/decorators.py", line 50, in handler
    return func(*args, **kwargs)
  File "/Users/teecoin/PycharmProjects/recommender_system_api/recommender_system_api/api/views.py", line 44, in get_custom_page_recommendations
    vendor_id_arr, rating_df, vendor_cosine_sim, neural_net_model)
  File "/Users/teecoin/PycharmProjects/recommender_system_api/recommender_system_api/vendors/vendor_hybrid_recommendation.py", line 79, in specific_recommendation
    rating_df=rating_df, vendor_id=vendor_id)
  File "/Users/teecoin/PycharmProjects/recommender_system_api/recommender_system_api/vendors/user_profiles.py", line 39, in build_user_profile_cb
    idx = indices[indices == vendor_id].index[0]
  File "/Users/teecoin/PycharmProjects/recommender_system_api/venv/lib/python3.6/site-packages/pandas/core/indexes/base.py", line 4280, in __getitem__
    return getitem(key)
IndexError: index 0 is out of bounds for axis 0 with size 0
ERROR 09/Oct/2019 10:43:16 basehttp [django.server:log_message:154] "GET /recommendation/custom/ HTTP/1.1" 500 19296
ERROR 09/Oct/2019 10:43:21 log [django.request:log_response:228] Internal Server Error: /recommendation/main/15091/2
Traceback (most recent call last):
  File "/Users/teecoin/PycharmProjects/recommender_system_api/venv/lib/python3.6/site-packages/django/core/handlers/exception.py", line 34, in inner
    response = get_response(request)
  File "/Users/teecoin/PycharmProjects/recommender_system_api/venv/lib/python3.6/site-packages/django/core/handlers/base.py", line 115, in _get_response
    response = self.process_exception_by_middleware(e, request)
  File "/Users/teecoin/PycharmProjects/recommender_system_api/venv/lib/python3.6/site-packages/django/core/handlers/base.py", line 113, in _get_response
    response = wrapped_callback(request, *callback_args, **callback_kwargs)
  File "/Users/teecoin/PycharmProjects/recommender_system_api/venv/lib/python3.6/site-packages/django/views/decorators/csrf.py", line 54, in wrapped_view
    return view_func(*args, **kwargs)
  File "/Users/teecoin/PycharmProjects/recommender_system_api/venv/lib/python3.6/site-packages/django/views/generic/base.py", line 71, in view
    return self.dispatch(request, *args, **kwargs)
  File "/Users/teecoin/PycharmProjects/recommender_system_api/venv/lib/python3.6/site-packages/rest_framework/views.py", line 505, in dispatch
    response = self.handle_exception(exc)
  File "/Users/teecoin/PycharmProjects/recommender_system_api/venv/lib/python3.6/site-packages/rest_framework/views.py", line 465, in handle_exception
    self.raise_uncaught_exception(exc)
  File "/Users/teecoin/PycharmProjects/recommender_system_api/venv/lib/python3.6/site-packages/rest_framework/views.py", line 476, in raise_uncaught_exception
    raise exc
  File "/Users/teecoin/PycharmProjects/recommender_system_api/venv/lib/python3.6/site-packages/rest_framework/views.py", line 502, in dispatch
    response = handler(request, *args, **kwargs)
  File "/Users/teecoin/PycharmProjects/recommender_system_api/venv/lib/python3.6/site-packages/rest_framework/decorators.py", line 50, in handler
    return func(*args, **kwargs)
  File "/Users/teecoin/PycharmProjects/recommender_system_api/recommender_system_api/api/views.py", line 27, in get_main_page_recommendations
    vendor_cosine_sim, neural_net_model, new_user, has_reviewed)
  File "/Users/teecoin/PycharmProjects/recommender_system_api/recommender_system_api/vendors/vendor_hybrid_recommendation.py", line 48, in main_page_recommendation
    vendor_recommendation_nn = build_user_profile_nn(user_id, gender, model=neural_net_model, rating_df=rating_df)
  File "/Users/teecoin/PycharmProjects/recommender_system_api/recommender_system_api/vendors/user_profiles.py", line 16, in build_user_profile_nn
    user_id = rating_df[rating_df.user_id == user_id].user_id.iloc[0]
  File "/Users/teecoin/PycharmProjects/recommender_system_api/venv/lib/python3.6/site-packages/pandas/core/indexing.py", line 1424, in __getitem__
    return self._getitem_axis(maybe_callable, axis=axis)
  File "/Users/teecoin/PycharmProjects/recommender_system_api/venv/lib/python3.6/site-packages/pandas/core/indexing.py", line 2157, in _getitem_axis
    self._validate_integer(key, axis)
  File "/Users/teecoin/PycharmProjects/recommender_system_api/venv/lib/python3.6/site-packages/pandas/core/indexing.py", line 2088, in _validate_integer
    raise IndexError("single positional indexer is out-of-bounds")
IndexError: single positional indexer is out-of-bounds
ERROR 09/Oct/2019 10:43:21 basehttp [django.server:log_message:154] "GET /recommendation/main/15091/2 HTTP/1.1" 500 19760
INFO 10/Oct/2019 07:38:58 autoreload [django.utils.autoreload:run_with_reloader:597] Watching for file changes with StatReloader
INFO 10/Oct/2019 07:49:22 autoreload [django.utils.autoreload:run_with_reloader:597] Watching for file changes with StatReloader
INFO 10/Oct/2019 07:59:43 autoreload [django.utils.autoreload:run_with_reloader:597] Watching for file changes with StatReloader
WARNING 10/Oct/2019 07:59:47 log [django.request:log_response:228] Not Found: /
WARNING 10/Oct/2019 07:59:47 basehttp [django.server:log_message:154] "GET / HTTP/1.1" 404 2038
WARNING 10/Oct/2019 07:59:48 log [django.request:log_response:228] Not Found: /favicon.ico
WARNING 10/Oct/2019 07:59:48 basehttp [django.server:log_message:154] "GET /favicon.ico HTTP/1.1" 404 2089
INFO 10/Oct/2019 08:02:33 autoreload [django.utils.autoreload:run_with_reloader:597] Watching for file changes with StatReloader
WARNING 10/Oct/2019 08:02:36 log [django.request:log_response:228] Not Found: /
WARNING 10/Oct/2019 08:02:36 basehttp [django.server:log_message:154] "GET / HTTP/1.1" 404 2038
INFO 10/Oct/2019 08:18:53 autoreload [django.utils.autoreload:run_with_reloader:597] Watching for file changes with StatReloader
INFO 10/Oct/2019 08:19:10 autoreload [django.utils.autoreload:run_with_reloader:597] Watching for file changes with StatReloader
INFO 10/Oct/2019 08:19:53 autoreload [django.utils.autoreload:run_with_reloader:597] Watching for file changes with StatReloader
INFO 10/Oct/2019 08:23:14 autoreload [django.utils.autoreload:run_with_reloader:597] Watching for file changes with StatReloader
INFO 10/Oct/2019 08:23:55 autoreload [django.utils.autoreload:run_with_reloader:597] Watching for file changes with StatReloader
ERROR 10/Oct/2019 08:24:24 log [django.request:log_response:228] Internal Server Error: /recommendation/custom/
Traceback (most recent call last):
  File "/Users/teecoin/PycharmProjects/recommender_env/lib/python3.7/site-packages/django/core/handlers/exception.py", line 34, in inner
    response = get_response(request)
  File "/Users/teecoin/PycharmProjects/recommender_env/lib/python3.7/site-packages/django/core/handlers/base.py", line 115, in _get_response
    response = self.process_exception_by_middleware(e, request)
  File "/Users/teecoin/PycharmProjects/recommender_env/lib/python3.7/site-packages/django/core/handlers/base.py", line 113, in _get_response
    response = wrapped_callback(request, *callback_args, **callback_kwargs)
  File "/Users/teecoin/PycharmProjects/recommender_env/lib/python3.7/site-packages/django/views/decorators/csrf.py", line 54, in wrapped_view
    return view_func(*args, **kwargs)
  File "/Users/teecoin/PycharmProjects/recommender_env/lib/python3.7/site-packages/django/views/generic/base.py", line 71, in view
    return self.dispatch(request, *args, **kwargs)
  File "/Users/teecoin/PycharmProjects/recommender_env/lib/python3.7/site-packages/rest_framework/views.py", line 505, in dispatch
    response = self.handle_exception(exc)
  File "/Users/teecoin/PycharmProjects/recommender_env/lib/python3.7/site-packages/rest_framework/views.py", line 465, in handle_exception
    self.raise_uncaught_exception(exc)
  File "/Users/teecoin/PycharmProjects/recommender_env/lib/python3.7/site-packages/rest_framework/views.py", line 476, in raise_uncaught_exception
    raise exc
  File "/Users/teecoin/PycharmProjects/recommender_env/lib/python3.7/site-packages/rest_framework/views.py", line 502, in dispatch
    response = handler(request, *args, **kwargs)
  File "/Users/teecoin/PycharmProjects/recommender_env/lib/python3.7/site-packages/rest_framework/decorators.py", line 50, in handler
    return func(*args, **kwargs)
  File "/Users/teecoin/PycharmProjects/recommender_system_api/recommender_system_api/api/views.py", line 44, in get_custom_page_recommendations
    vendor_id_arr, rating_df, vendor_cosine_sim, neural_net_model)
  File "/Users/teecoin/PycharmProjects/recommender_system_api/recommender_system_api/vendors/vendor_hybrid_recommendation.py", line 79, in specific_recommendation
    rating_df=rating_df, vendor_id=vendor_id)
  File "/Users/teecoin/PycharmProjects/recommender_system_api/recommender_system_api/vendors/user_profiles.py", line 39, in build_user_profile_cb
    idx = indices[indices == vendor_id].index[0]
  File "/Users/teecoin/PycharmProjects/recommender_env/lib/python3.7/site-packages/pandas/core/indexes/base.py", line 4280, in __getitem__
    return getitem(key)
IndexError: index 0 is out of bounds for axis 0 with size 0
ERROR 10/Oct/2019 08:24:24 basehttp [django.server:log_message:154] "GET /recommendation/custom/ HTTP/1.1" 500 20286
WARNING 10/Oct/2019 08:24:25 log [django.request:log_response:228] Not Found: /favicon.ico
WARNING 10/Oct/2019 08:24:25 basehttp [django.server:log_message:154] "GET /favicon.ico HTTP/1.1" 404 2089
INFO 10/Oct/2019 08:35:31 autoreload [django.utils.autoreload:trigger_reload:217] /Users/teecoin/PycharmProjects/recommender_system_api/recommender_system_api/vendors/vendor_hybrid_recommendation.py changed, reloading.
INFO 10/Oct/2019 08:35:33 autoreload [django.utils.autoreload:run_with_reloader:597] Watching for file changes with StatReloader
INFO 10/Oct/2019 08:36:14 autoreload [django.utils.autoreload:trigger_reload:217] /Users/teecoin/PycharmProjects/recommender_system_api/recommender_system_api/vendors/vendor_hybrid_recommendation.py changed, reloading.
INFO 10/Oct/2019 08:36:15 autoreload [django.utils.autoreload:run_with_reloader:597] Watching for file changes with StatReloader
INFO 10/Oct/2019 08:39:29 autoreload [django.utils.autoreload:run_with_reloader:597] Watching for file changes with StatReloader
INFO 10/Oct/2019 09:06:59 autoreload [django.utils.autoreload:trigger_reload:217] /Users/teecoin/PycharmProjects/recommender_system_api/recommender_system_api/vendors/vendor_hybrid_recommendation.py changed, reloading.
INFO 10/Oct/2019 09:07:01 autoreload [django.utils.autoreload:run_with_reloader:597] Watching for file changes with StatReloader
INFO 10/Oct/2019 09:08:53 autoreload [django.utils.autoreload:run_with_reloader:597] Watching for file changes with StatReloader
INFO 10/Oct/2019 09:12:19 autoreload [django.utils.autoreload:trigger_reload:217] /Users/teecoin/PycharmProjects/recommender_system_api/recommender_system_api/api/views.py changed, reloading.
INFO 10/Oct/2019 09:12:21 autoreload [django.utils.autoreload:run_with_reloader:597] Watching for file changes with StatReloader
INFO 10/Oct/2019 09:14:55 autoreload [django.utils.autoreload:run_with_reloader:597] Watching for file changes with StatReloader
INFO 10/Oct/2019 09:17:53 autoreload [django.utils.autoreload:trigger_reload:217] /Users/teecoin/PycharmProjects/recommender_system_api/config/settings/base.py changed, reloading.
INFO 10/Oct/2019 09:17:55 autoreload [django.utils.autoreload:run_with_reloader:597] Watching for file changes with StatReloader
INFO 10/Oct/2019 09:18:00 autoreload [django.utils.autoreload:run_with_reloader:597] Watching for file changes with StatReloader
INFO 10/Oct/2019 09:19:14 autoreload [django.utils.autoreload:trigger_reload:217] /Users/teecoin/PycharmProjects/recommender_system_api/recommender_system_api/api/urls.py changed, reloading.
INFO 10/Oct/2019 09:19:15 autoreload [django.utils.autoreload:run_with_reloader:597] Watching for file changes with StatReloader
INFO 10/Oct/2019 09:20:22 autoreload [django.utils.autoreload:run_with_reloader:597] Watching for file changes with StatReloader
INFO 10/Oct/2019 09:23:08 autoreload [django.utils.autoreload:run_with_reloader:597] Watching for file changes with StatReloader
ERROR 10/Oct/2019 09:23:19 log [django.request:log_response:228] Internal Server Error: /recommendation/custom/
Traceback (most recent call last):
  File "/Users/teecoin/PycharmProjects/recommender_env/lib/python3.7/site-packages/django/core/handlers/exception.py", line 34, in inner
    response = get_response(request)
  File "/Users/teecoin/PycharmProjects/recommender_env/lib/python3.7/site-packages/django/core/handlers/base.py", line 115, in _get_response
    response = self.process_exception_by_middleware(e, request)
  File "/Users/teecoin/PycharmProjects/recommender_env/lib/python3.7/site-packages/django/core/handlers/base.py", line 113, in _get_response
    response = wrapped_callback(request, *callback_args, **callback_kwargs)
  File "/Users/teecoin/PycharmProjects/recommender_env/lib/python3.7/site-packages/django/views/decorators/csrf.py", line 54, in wrapped_view
    return view_func(*args, **kwargs)
  File "/Users/teecoin/PycharmProjects/recommender_env/lib/python3.7/site-packages/django/views/generic/base.py", line 71, in view
    return self.dispatch(request, *args, **kwargs)
  File "/Users/teecoin/PycharmProjects/recommender_env/lib/python3.7/site-packages/rest_framework/views.py", line 505, in dispatch
    response = self.handle_exception(exc)
  File "/Users/teecoin/PycharmProjects/recommender_env/lib/python3.7/site-packages/rest_framework/views.py", line 465, in handle_exception
    self.raise_uncaught_exception(exc)
  File "/Users/teecoin/PycharmProjects/recommender_env/lib/python3.7/site-packages/rest_framework/views.py", line 476, in raise_uncaught_exception
    raise exc
  File "/Users/teecoin/PycharmProjects/recommender_env/lib/python3.7/site-packages/rest_framework/views.py", line 502, in dispatch
    response = handler(request, *args, **kwargs)
  File "/Users/teecoin/PycharmProjects/recommender_env/lib/python3.7/site-packages/rest_framework/decorators.py", line 50, in handler
    return func(*args, **kwargs)
  File "/Users/teecoin/PycharmProjects/recommender_system_api/recommender_system_api/api/views.py", line 44, in get_custom_page_recommendations
    vendor_id_arr, rating_df, vendor_cosine_sim, neural_net_model)
  File "/Users/teecoin/PycharmProjects/recommender_system_api/recommender_system_api/vendors/vendor_hybrid_recommendation.py", line 83, in specific_recommendation
    rating_df=rating_df, vendor_id=vendor_id)
  File "/Users/teecoin/PycharmProjects/recommender_system_api/recommender_system_api/vendors/user_profiles.py", line 39, in build_user_profile_cb
    idx = indices[indices == vendor_id].index[0]
  File "/Users/teecoin/PycharmProjects/recommender_env/lib/python3.7/site-packages/pandas/core/indexes/base.py", line 4280, in __getitem__
    return getitem(key)
IndexError: index 0 is out of bounds for axis 0 with size 0
ERROR 10/Oct/2019 09:23:19 basehttp [django.server:log_message:154] "GET /recommendation/custom/ HTTP/1.1" 500 27
WARNING 10/Oct/2019 09:23:31 log [django.request:log_response:228] Not Found: /
WARNING 10/Oct/2019 09:23:31 basehttp [django.server:log_message:154] "GET / HTTP/1.1" 404 77
WARNING 10/Oct/2019 09:23:32 log [django.request:log_response:228] Not Found: /favicon.ico
WARNING 10/Oct/2019 09:23:32 basehttp [django.server:log_message:154] "GET /favicon.ico HTTP/1.1" 404 77
WARNING 10/Oct/2019 09:24:14 log [django.request:log_response:228] Not Found: /
WARNING 10/Oct/2019 09:24:14 basehttp [django.server:log_message:154] "GET / HTTP/1.1" 404 77
INFO 10/Oct/2019 09:24:22 basehttp [django.server:log_message:154] "GET /admin HTTP/1.1" 301 0
INFO 10/Oct/2019 09:24:22 basehttp [django.server:log_message:154] "GET /admin/ HTTP/1.1" 302 0
INFO 10/Oct/2019 09:24:22 basehttp [django.server:log_message:154] "GET /admin/login/?next=/admin/ HTTP/1.1" 200 1819
WARNING 10/Oct/2019 09:24:22 log [django.request:log_response:228] Not Found: /static/admin/css/base.css
WARNING 10/Oct/2019 09:24:22 log [django.request:log_response:228] Not Found: /static/admin/css/login.css
WARNING 10/Oct/2019 09:24:22 log [django.request:log_response:228] Not Found: /static/admin/css/responsive.css
WARNING 10/Oct/2019 09:24:22 basehttp [django.server:log_message:154] "GET /static/admin/css/login.css HTTP/1.1" 404 77
WARNING 10/Oct/2019 09:24:22 basehttp [django.server:log_message:154] "GET /static/admin/css/base.css HTTP/1.1" 404 77
WARNING 10/Oct/2019 09:24:22 basehttp [django.server:log_message:154] "GET /static/admin/css/responsive.css HTTP/1.1" 404 77
INFO 10/Oct/2019 09:25:01 autoreload [django.utils.autoreload:run_with_reloader:597] Watching for file changes with StatReloader
INFO 10/Oct/2019 09:29:00 autoreload [django.utils.autoreload:run_with_reloader:597] Watching for file changes with StatReloader
WARNING 10/Oct/2019 09:29:11 log [django.request:log_response:228] Not Found: /
WARNING 10/Oct/2019 09:29:11 basehttp [django.server:log_message:154] "GET / HTTP/1.1" 404 77
WARNING 10/Oct/2019 09:29:11 log [django.request:log_response:228] Not Found: /favicon.ico
WARNING 10/Oct/2019 09:29:11 basehttp [django.server:log_message:154] "GET /favicon.ico HTTP/1.1" 404 77
ERROR 10/Oct/2019 09:29:16 log [django.request:log_response:228] Internal Server Error: /recommendation/custom/
Traceback (most recent call last):
  File "/Users/teecoin/PycharmProjects/recommender_env/lib/python3.7/site-packages/django/core/handlers/exception.py", line 34, in inner
    response = get_response(request)
  File "/Users/teecoin/PycharmProjects/recommender_env/lib/python3.7/site-packages/django/core/handlers/base.py", line 115, in _get_response
    response = self.process_exception_by_middleware(e, request)
  File "/Users/teecoin/PycharmProjects/recommender_env/lib/python3.7/site-packages/django/core/handlers/base.py", line 113, in _get_response
    response = wrapped_callback(request, *callback_args, **callback_kwargs)
  File "/Users/teecoin/PycharmProjects/recommender_env/lib/python3.7/site-packages/django/views/decorators/csrf.py", line 54, in wrapped_view
    return view_func(*args, **kwargs)
  File "/Users/teecoin/PycharmProjects/recommender_env/lib/python3.7/site-packages/django/views/generic/base.py", line 71, in view
    return self.dispatch(request, *args, **kwargs)
  File "/Users/teecoin/PycharmProjects/recommender_env/lib/python3.7/site-packages/rest_framework/views.py", line 505, in dispatch
    response = self.handle_exception(exc)
  File "/Users/teecoin/PycharmProjects/recommender_env/lib/python3.7/site-packages/rest_framework/views.py", line 465, in handle_exception
    self.raise_uncaught_exception(exc)
  File "/Users/teecoin/PycharmProjects/recommender_env/lib/python3.7/site-packages/rest_framework/views.py", line 476, in raise_uncaught_exception
    raise exc
  File "/Users/teecoin/PycharmProjects/recommender_env/lib/python3.7/site-packages/rest_framework/views.py", line 502, in dispatch
    response = handler(request, *args, **kwargs)
  File "/Users/teecoin/PycharmProjects/recommender_env/lib/python3.7/site-packages/rest_framework/decorators.py", line 50, in handler
    return func(*args, **kwargs)
  File "/Users/teecoin/PycharmProjects/recommender_system_api/recommender_system_api/api/views.py", line 44, in get_custom_page_recommendations
    vendor_id_arr, rating_df, vendor_cosine_sim, neural_net_model)
  File "/Users/teecoin/PycharmProjects/recommender_system_api/recommender_system_api/vendors/vendor_hybrid_recommendation.py", line 83, in specific_recommendation
    rating_df=rating_df, vendor_id=vendor_id)
  File "/Users/teecoin/PycharmProjects/recommender_system_api/recommender_system_api/vendors/user_profiles.py", line 39, in build_user_profile_cb
    idx = indices[indices == vendor_id].index[0]
  File "/Users/teecoin/PycharmProjects/recommender_env/lib/python3.7/site-packages/pandas/core/indexes/base.py", line 4280, in __getitem__
    return getitem(key)
IndexError: index 0 is out of bounds for axis 0 with size 0
ERROR 10/Oct/2019 09:29:16 basehttp [django.server:log_message:154] "GET /recommendation/custom/ HTTP/1.1" 500 27
ERROR 10/Oct/2019 09:30:26 log [django.request:log_response:228] Internal Server Error: /recommendation/main/
Traceback (most recent call last):
  File "/Users/teecoin/PycharmProjects/recommender_env/lib/python3.7/site-packages/django/core/handlers/exception.py", line 34, in inner
    response = get_response(request)
  File "/Users/teecoin/PycharmProjects/recommender_env/lib/python3.7/site-packages/django/core/handlers/base.py", line 115, in _get_response
    response = self.process_exception_by_middleware(e, request)
  File "/Users/teecoin/PycharmProjects/recommender_env/lib/python3.7/site-packages/django/core/handlers/base.py", line 113, in _get_response
    response = wrapped_callback(request, *callback_args, **callback_kwargs)
  File "/Users/teecoin/PycharmProjects/recommender_env/lib/python3.7/site-packages/django/views/decorators/csrf.py", line 54, in wrapped_view
    return view_func(*args, **kwargs)
  File "/Users/teecoin/PycharmProjects/recommender_env/lib/python3.7/site-packages/django/views/generic/base.py", line 71, in view
    return self.dispatch(request, *args, **kwargs)
  File "/Users/teecoin/PycharmProjects/recommender_env/lib/python3.7/site-packages/rest_framework/views.py", line 505, in dispatch
    response = self.handle_exception(exc)
  File "/Users/teecoin/PycharmProjects/recommender_env/lib/python3.7/site-packages/rest_framework/views.py", line 465, in handle_exception
    self.raise_uncaught_exception(exc)
  File "/Users/teecoin/PycharmProjects/recommender_env/lib/python3.7/site-packages/rest_framework/views.py", line 476, in raise_uncaught_exception
    raise exc
  File "/Users/teecoin/PycharmProjects/recommender_env/lib/python3.7/site-packages/rest_framework/views.py", line 502, in dispatch
    response = handler(request, *args, **kwargs)
  File "/Users/teecoin/PycharmProjects/recommender_env/lib/python3.7/site-packages/rest_framework/decorators.py", line 50, in handler
    return func(*args, **kwargs)
  File "/Users/teecoin/PycharmProjects/recommender_system_api/recommender_system_api/api/views.py", line 27, in get_main_page_recommendations
    vendor_cosine_sim, neural_net_model, new_user, has_reviewed)
  File "/Users/teecoin/PycharmProjects/recommender_system_api/recommender_system_api/vendors/vendor_hybrid_recommendation.py", line 48, in main_page_recommendation
    vendor_recommendation_nn = build_user_profile_nn(user_id, gender, model=neural_net_model, rating_df=rating_df)
  File "/Users/teecoin/PycharmProjects/recommender_system_api/recommender_system_api/vendors/user_profiles.py", line 19, in build_user_profile_nn
    predictions = model.predict([user_id, gender, vendor_id, vd_country_id])
  File "/Users/teecoin/PycharmProjects/recommender_env/lib/python3.7/site-packages/tensorflow_core/python/keras/engine/training.py", line 909, in predict
    use_multiprocessing=use_multiprocessing)
  File "/Users/teecoin/PycharmProjects/recommender_env/lib/python3.7/site-packages/tensorflow_core/python/keras/engine/training_v2.py", line 462, in predict
    steps=steps, callbacks=callbacks, **kwargs)
  File "/Users/teecoin/PycharmProjects/recommender_env/lib/python3.7/site-packages/tensorflow_core/python/keras/engine/training_v2.py", line 444, in _model_iteration
    total_epochs=1)
  File "/Users/teecoin/PycharmProjects/recommender_env/lib/python3.7/site-packages/tensorflow_core/python/keras/engine/training_v2.py", line 123, in run_one_epoch
    batch_outs = execution_function(iterator)
  File "/Users/teecoin/PycharmProjects/recommender_env/lib/python3.7/site-packages/tensorflow_core/python/keras/engine/training_v2_utils.py", line 86, in execution_function
    distributed_function(input_fn))
  File "/Users/teecoin/PycharmProjects/recommender_env/lib/python3.7/site-packages/tensorflow_core/python/eager/def_function.py", line 457, in __call__
    result = self._call(*args, **kwds)
  File "/Users/teecoin/PycharmProjects/recommender_env/lib/python3.7/site-packages/tensorflow_core/python/eager/def_function.py", line 503, in _call
    self._initialize(args, kwds, add_initializers_to=initializer_map)
  File "/Users/teecoin/PycharmProjects/recommender_env/lib/python3.7/site-packages/tensorflow_core/python/eager/def_function.py", line 408, in _initialize
    *args, **kwds))
  File "/Users/teecoin/PycharmProjects/recommender_env/lib/python3.7/site-packages/tensorflow_core/python/eager/function.py", line 1848, in _get_concrete_function_internal_garbage_collected
    graph_function, _, _ = self._maybe_define_function(args, kwargs)
  File "/Users/teecoin/PycharmProjects/recommender_env/lib/python3.7/site-packages/tensorflow_core/python/eager/function.py", line 2150, in _maybe_define_function
    graph_function = self._create_graph_function(args, kwargs)
  File "/Users/teecoin/PycharmProjects/recommender_env/lib/python3.7/site-packages/tensorflow_core/python/eager/function.py", line 2041, in _create_graph_function
    capture_by_value=self._capture_by_value),
  File "/Users/teecoin/PycharmProjects/recommender_env/lib/python3.7/site-packages/tensorflow_core/python/framework/func_graph.py", line 915, in func_graph_from_py_func
    func_outputs = python_func(*func_args, **func_kwargs)
  File "/Users/teecoin/PycharmProjects/recommender_env/lib/python3.7/site-packages/tensorflow_core/python/eager/def_function.py", line 358, in wrapped_fn
    return weak_wrapped_fn().__wrapped__(*args, **kwds)
  File "/Users/teecoin/PycharmProjects/recommender_env/lib/python3.7/site-packages/tensorflow_core/python/keras/engine/training_v2_utils.py", line 73, in distributed_function
    per_replica_function, args=(model, x, y, sample_weights))
  File "/Users/teecoin/PycharmProjects/recommender_env/lib/python3.7/site-packages/tensorflow_core/python/distribute/distribute_lib.py", line 760, in experimental_run_v2
    return self._extended.call_for_each_replica(fn, args=args, kwargs=kwargs)
  File "/Users/teecoin/PycharmProjects/recommender_env/lib/python3.7/site-packages/tensorflow_core/python/distribute/distribute_lib.py", line 1787, in call_for_each_replica
    return self._call_for_each_replica(fn, args, kwargs)
  File "/Users/teecoin/PycharmProjects/recommender_env/lib/python3.7/site-packages/tensorflow_core/python/distribute/distribute_lib.py", line 2132, in _call_for_each_replica
    return fn(*args, **kwargs)
  File "/Users/teecoin/PycharmProjects/recommender_env/lib/python3.7/site-packages/tensorflow_core/python/autograph/impl/api.py", line 292, in wrapper
    return func(*args, **kwargs)
  File "/Users/teecoin/PycharmProjects/recommender_env/lib/python3.7/site-packages/tensorflow_core/python/keras/engine/training_v2_utils.py", line 162, in _predict_on_batch
    return predict_on_batch(model, x)
  File "/Users/teecoin/PycharmProjects/recommender_env/lib/python3.7/site-packages/tensorflow_core/python/keras/engine/training_v2_utils.py", line 370, in predict_on_batch
    return model(inputs)  # pylint: disable=not-callable
  File "/Users/teecoin/PycharmProjects/recommender_env/lib/python3.7/site-packages/tensorflow_core/python/keras/engine/base_layer.py", line 847, in __call__
    outputs = call_fn(cast_inputs, *args, **kwargs)
  File "/Users/teecoin/PycharmProjects/recommender_env/lib/python3.7/site-packages/tensorflow_core/python/keras/saving/saved_model/utils.py", line 57, in return_outputs_and_add_losses
    outputs, losses = fn(inputs, *args, **kwargs)
  File "/Users/teecoin/PycharmProjects/recommender_env/lib/python3.7/site-packages/tensorflow_core/python/keras/saving/saved_model/utils.py", line 111, in wrap_with_training_arg
    lambda: replace_training_and_call(False))
  File "/Users/teecoin/PycharmProjects/recommender_env/lib/python3.7/site-packages/tensorflow_core/python/keras/utils/tf_utils.py", line 59, in smart_cond
    pred, true_fn=true_fn, false_fn=false_fn, name=name)
  File "/Users/teecoin/PycharmProjects/recommender_env/lib/python3.7/site-packages/tensorflow_core/python/framework/smart_cond.py", line 56, in smart_cond
    return false_fn()
  File "/Users/teecoin/PycharmProjects/recommender_env/lib/python3.7/site-packages/tensorflow_core/python/keras/saving/saved_model/utils.py", line 111, in <lambda>
    lambda: replace_training_and_call(False))
  File "/Users/teecoin/PycharmProjects/recommender_env/lib/python3.7/site-packages/tensorflow_core/python/keras/saving/saved_model/utils.py", line 106, in replace_training_and_call
    return wrapped_call(*args, **kwargs)
  File "/Users/teecoin/PycharmProjects/recommender_env/lib/python3.7/site-packages/tensorflow_core/python/eager/def_function.py", line 457, in __call__
    result = self._call(*args, **kwds)
  File "/Users/teecoin/PycharmProjects/recommender_env/lib/python3.7/site-packages/tensorflow_core/python/eager/def_function.py", line 494, in _call
    results = self._stateful_fn(*args, **kwds)
  File "/Users/teecoin/PycharmProjects/recommender_env/lib/python3.7/site-packages/tensorflow_core/python/eager/function.py", line 1822, in __call__
    graph_function, args, kwargs = self._maybe_define_function(args, kwargs)
  File "/Users/teecoin/PycharmProjects/recommender_env/lib/python3.7/site-packages/tensorflow_core/python/eager/function.py", line 2150, in _maybe_define_function
    graph_function = self._create_graph_function(args, kwargs)
  File "/Users/teecoin/PycharmProjects/recommender_env/lib/python3.7/site-packages/tensorflow_core/python/eager/function.py", line 2041, in _create_graph_function
    capture_by_value=self._capture_by_value),
  File "/Users/teecoin/PycharmProjects/recommender_env/lib/python3.7/site-packages/tensorflow_core/python/framework/func_graph.py", line 915, in func_graph_from_py_func
    func_outputs = python_func(*func_args, **func_kwargs)
  File "/Users/teecoin/PycharmProjects/recommender_env/lib/python3.7/site-packages/tensorflow_core/python/eager/def_function.py", line 358, in wrapped_fn
    return weak_wrapped_fn().__wrapped__(*args, **kwds)
  File "/Users/teecoin/PycharmProjects/recommender_env/lib/python3.7/site-packages/tensorflow_core/python/saved_model/function_deserialization.py", line 262, in restored_function_body
    "\n\n".join(signature_descriptions)))
ValueError: Could not find matching function to call loaded from the SavedModel. Got:
  Positional arguments (3 total):
    * [<tf.Tensor 'inputs:0' shape=(None, 1) dtype=int64>, <tf.Tensor 'inputs_1:0' shape=(None, 1) dtype=int64>, <tf.Tensor 'inputs_2:0' shape=(None, 1) dtype=int64>, <tf.Tensor 'inputs_3:0' shape=(None, 1) dtype=int64>]
    * False
    * None
  Keyword arguments: {}

Expected these arguments to match one of the following 4 option(s):

Option 1:
  Positional arguments (3 total):
    * [TensorSpec(shape=(None, 1), dtype=tf.float32, name='User-Input'), TensorSpec(shape=(None, 1), dtype=tf.float32, name='Gender-Input'), TensorSpec(shape=(None, 1), dtype=tf.float32, name='Vendor-Input'), TensorSpec(shape=(None, 1), dtype=tf.float32, name='Vendor-Country-Input')]
    * True
    * None
  Keyword arguments: {}

Option 2:
  Positional arguments (3 total):
    * [TensorSpec(shape=(None, 1), dtype=tf.float32, name='inputs/0'), TensorSpec(shape=(None, 1), dtype=tf.float32, name='inputs/1'), TensorSpec(shape=(None, 1), dtype=tf.float32, name='inputs/2'), TensorSpec(shape=(None, 1), dtype=tf.float32, name='inputs/3')]
    * True
    * None
  Keyword arguments: {}

Option 3:
  Positional arguments (3 total):
    * [TensorSpec(shape=(None, 1), dtype=tf.float32, name='inputs/0'), TensorSpec(shape=(None, 1), dtype=tf.float32, name='inputs/1'), TensorSpec(shape=(None, 1), dtype=tf.float32, name='inputs/2'), TensorSpec(shape=(None, 1), dtype=tf.float32, name='inputs/3')]
    * False
    * None
  Keyword arguments: {}

Option 4:
  Positional arguments (3 total):
    * [TensorSpec(shape=(None, 1), dtype=tf.float32, name='User-Input'), TensorSpec(shape=(None, 1), dtype=tf.float32, name='Gender-Input'), TensorSpec(shape=(None, 1), dtype=tf.float32, name='Vendor-Input'), TensorSpec(shape=(None, 1), dtype=tf.float32, name='Vendor-Country-Input')]
    * False
    * None
  Keyword arguments: {}
ERROR 10/Oct/2019 09:30:26 basehttp [django.server:log_message:154] "GET /recommendation/main/ HTTP/1.1" 500 27
INFO 10/Oct/2019 09:31:29 autoreload [django.utils.autoreload:trigger_reload:217] /Users/teecoin/PycharmProjects/recommender_system_api/recommender_system_api/vendors/vendor_hybrid_recommendation.py changed, reloading.
INFO 10/Oct/2019 09:31:30 autoreload [django.utils.autoreload:run_with_reloader:597] Watching for file changes with StatReloader
INFO 10/Oct/2019 09:31:42 autoreload [django.utils.autoreload:trigger_reload:217] /Users/teecoin/PycharmProjects/recommender_system_api/recommender_system_api/vendors/vendor_hybrid_recommendation.py changed, reloading.
INFO 10/Oct/2019 09:31:43 autoreload [django.utils.autoreload:run_with_reloader:597] Watching for file changes with StatReloader
INFO 10/Oct/2019 09:33:11 autoreload [django.utils.autoreload:run_with_reloader:597] Watching for file changes with StatReloader
ERROR 10/Oct/2019 09:33:17 log [django.request:log_response:228] Internal Server Error: /recommendation/custom/
Traceback (most recent call last):
  File "/Users/teecoin/PycharmProjects/recommender_env/lib/python3.7/site-packages/django/core/handlers/exception.py", line 34, in inner
    response = get_response(request)
  File "/Users/teecoin/PycharmProjects/recommender_env/lib/python3.7/site-packages/django/core/handlers/base.py", line 115, in _get_response
    response = self.process_exception_by_middleware(e, request)
  File "/Users/teecoin/PycharmProjects/recommender_env/lib/python3.7/site-packages/django/core/handlers/base.py", line 113, in _get_response
    response = wrapped_callback(request, *callback_args, **callback_kwargs)
  File "/Users/teecoin/PycharmProjects/recommender_env/lib/python3.7/site-packages/django/views/decorators/csrf.py", line 54, in wrapped_view
    return view_func(*args, **kwargs)
  File "/Users/teecoin/PycharmProjects/recommender_env/lib/python3.7/site-packages/django/views/generic/base.py", line 71, in view
    return self.dispatch(request, *args, **kwargs)
  File "/Users/teecoin/PycharmProjects/recommender_env/lib/python3.7/site-packages/rest_framework/views.py", line 505, in dispatch
    response = self.handle_exception(exc)
  File "/Users/teecoin/PycharmProjects/recommender_env/lib/python3.7/site-packages/rest_framework/views.py", line 465, in handle_exception
    self.raise_uncaught_exception(exc)
  File "/Users/teecoin/PycharmProjects/recommender_env/lib/python3.7/site-packages/rest_framework/views.py", line 476, in raise_uncaught_exception
    raise exc
  File "/Users/teecoin/PycharmProjects/recommender_env/lib/python3.7/site-packages/rest_framework/views.py", line 502, in dispatch
    response = handler(request, *args, **kwargs)
  File "/Users/teecoin/PycharmProjects/recommender_env/lib/python3.7/site-packages/rest_framework/decorators.py", line 50, in handler
    return func(*args, **kwargs)
  File "/Users/teecoin/PycharmProjects/recommender_system_api/recommender_system_api/api/views.py", line 44, in get_custom_page_recommendations
    vendor_id_arr, rating_df, vendor_cosine_sim, neural_net_model)
  File "/Users/teecoin/PycharmProjects/recommender_system_api/recommender_system_api/vendors/vendor_hybrid_recommendation.py", line 83, in specific_recommendation
    rating_df=rating_df, vendor_id=vendor_id)
  File "/Users/teecoin/PycharmProjects/recommender_system_api/recommender_system_api/vendors/user_profiles.py", line 39, in build_user_profile_cb
    idx = indices[indices == vendor_id].index[0]
  File "/Users/teecoin/PycharmProjects/recommender_env/lib/python3.7/site-packages/pandas/core/indexes/base.py", line 4280, in __getitem__
    return getitem(key)
IndexError: index 0 is out of bounds for axis 0 with size 0
ERROR 10/Oct/2019 09:33:17 basehttp [django.server:log_message:154] "GET /recommendation/custom/ HTTP/1.1" 500 27
ERROR 10/Oct/2019 09:33:18 log [django.request:log_response:228] Internal Server Error: /recommendation/custom/
Traceback (most recent call last):
  File "/Users/teecoin/PycharmProjects/recommender_env/lib/python3.7/site-packages/django/core/handlers/exception.py", line 34, in inner
    response = get_response(request)
  File "/Users/teecoin/PycharmProjects/recommender_env/lib/python3.7/site-packages/django/core/handlers/base.py", line 115, in _get_response
    response = self.process_exception_by_middleware(e, request)
  File "/Users/teecoin/PycharmProjects/recommender_env/lib/python3.7/site-packages/django/core/handlers/base.py", line 113, in _get_response
    response = wrapped_callback(request, *callback_args, **callback_kwargs)
  File "/Users/teecoin/PycharmProjects/recommender_env/lib/python3.7/site-packages/django/views/decorators/csrf.py", line 54, in wrapped_view
    return view_func(*args, **kwargs)
  File "/Users/teecoin/PycharmProjects/recommender_env/lib/python3.7/site-packages/django/views/generic/base.py", line 71, in view
    return self.dispatch(request, *args, **kwargs)
  File "/Users/teecoin/PycharmProjects/recommender_env/lib/python3.7/site-packages/rest_framework/views.py", line 505, in dispatch
    response = self.handle_exception(exc)
  File "/Users/teecoin/PycharmProjects/recommender_env/lib/python3.7/site-packages/rest_framework/views.py", line 465, in handle_exception
    self.raise_uncaught_exception(exc)
  File "/Users/teecoin/PycharmProjects/recommender_env/lib/python3.7/site-packages/rest_framework/views.py", line 476, in raise_uncaught_exception
    raise exc
  File "/Users/teecoin/PycharmProjects/recommender_env/lib/python3.7/site-packages/rest_framework/views.py", line 502, in dispatch
    response = handler(request, *args, **kwargs)
  File "/Users/teecoin/PycharmProjects/recommender_env/lib/python3.7/site-packages/rest_framework/decorators.py", line 50, in handler
    return func(*args, **kwargs)
  File "/Users/teecoin/PycharmProjects/recommender_system_api/recommender_system_api/api/views.py", line 44, in get_custom_page_recommendations
    vendor_id_arr, rating_df, vendor_cosine_sim, neural_net_model)
  File "/Users/teecoin/PycharmProjects/recommender_system_api/recommender_system_api/vendors/vendor_hybrid_recommendation.py", line 83, in specific_recommendation
    rating_df=rating_df, vendor_id=vendor_id)
  File "/Users/teecoin/PycharmProjects/recommender_system_api/recommender_system_api/vendors/user_profiles.py", line 39, in build_user_profile_cb
    idx = indices[indices == vendor_id].index[0]
  File "/Users/teecoin/PycharmProjects/recommender_env/lib/python3.7/site-packages/pandas/core/indexes/base.py", line 4280, in __getitem__
    return getitem(key)
IndexError: index 0 is out of bounds for axis 0 with size 0
ERROR 10/Oct/2019 09:33:18 basehttp [django.server:log_message:154] "GET /recommendation/custom/ HTTP/1.1" 500 27
WARNING 10/Oct/2019 09:33:30 log [django.request:log_response:228] Not Found: /favicon.ico
WARNING 10/Oct/2019 09:33:30 basehttp [django.server:log_message:154] "GET /favicon.ico HTTP/1.1" 404 77
ERROR 10/Oct/2019 09:33:35 log [django.request:log_response:228] Internal Server Error: /recommendation/custom/
Traceback (most recent call last):
  File "/Users/teecoin/PycharmProjects/recommender_env/lib/python3.7/site-packages/django/core/handlers/exception.py", line 34, in inner
    response = get_response(request)
  File "/Users/teecoin/PycharmProjects/recommender_env/lib/python3.7/site-packages/django/core/handlers/base.py", line 115, in _get_response
    response = self.process_exception_by_middleware(e, request)
  File "/Users/teecoin/PycharmProjects/recommender_env/lib/python3.7/site-packages/django/core/handlers/base.py", line 113, in _get_response
    response = wrapped_callback(request, *callback_args, **callback_kwargs)
  File "/Users/teecoin/PycharmProjects/recommender_env/lib/python3.7/site-packages/django/views/decorators/csrf.py", line 54, in wrapped_view
    return view_func(*args, **kwargs)
  File "/Users/teecoin/PycharmProjects/recommender_env/lib/python3.7/site-packages/django/views/generic/base.py", line 71, in view
    return self.dispatch(request, *args, **kwargs)
  File "/Users/teecoin/PycharmProjects/recommender_env/lib/python3.7/site-packages/rest_framework/views.py", line 505, in dispatch
    response = self.handle_exception(exc)
  File "/Users/teecoin/PycharmProjects/recommender_env/lib/python3.7/site-packages/rest_framework/views.py", line 465, in handle_exception
    self.raise_uncaught_exception(exc)
  File "/Users/teecoin/PycharmProjects/recommender_env/lib/python3.7/site-packages/rest_framework/views.py", line 476, in raise_uncaught_exception
    raise exc
  File "/Users/teecoin/PycharmProjects/recommender_env/lib/python3.7/site-packages/rest_framework/views.py", line 502, in dispatch
    response = handler(request, *args, **kwargs)
  File "/Users/teecoin/PycharmProjects/recommender_env/lib/python3.7/site-packages/rest_framework/decorators.py", line 50, in handler
    return func(*args, **kwargs)
  File "/Users/teecoin/PycharmProjects/recommender_system_api/recommender_system_api/api/views.py", line 44, in get_custom_page_recommendations
    vendor_id_arr, rating_df, vendor_cosine_sim, neural_net_model)
  File "/Users/teecoin/PycharmProjects/recommender_system_api/recommender_system_api/vendors/vendor_hybrid_recommendation.py", line 83, in specific_recommendation
    rating_df=rating_df, vendor_id=vendor_id)
  File "/Users/teecoin/PycharmProjects/recommender_system_api/recommender_system_api/vendors/user_profiles.py", line 39, in build_user_profile_cb
    idx = indices[indices == vendor_id].index[0]
  File "/Users/teecoin/PycharmProjects/recommender_env/lib/python3.7/site-packages/pandas/core/indexes/base.py", line 4280, in __getitem__
    return getitem(key)
IndexError: index 0 is out of bounds for axis 0 with size 0
ERROR 10/Oct/2019 09:33:35 basehttp [django.server:log_message:154] "GET /recommendation/custom/ HTTP/1.1" 500 27
INFO 10/Oct/2019 09:33:48 basehttp [django.server:log_message:154] "GET /recommendation/main/ HTTP/1.1" 200 3729
INFO 10/Oct/2019 09:33:58 basehttp [django.server:log_message:154] "GET /recommendation/main/ HTTP/1.1" 200 3729
ERROR 10/Oct/2019 09:40:33 log [django.request:log_response:228] Internal Server Error: /recommendation/custom/
Traceback (most recent call last):
  File "/Users/teecoin/PycharmProjects/recommender_env/lib/python3.7/site-packages/django/core/handlers/exception.py", line 34, in inner
    response = get_response(request)
  File "/Users/teecoin/PycharmProjects/recommender_env/lib/python3.7/site-packages/django/core/handlers/base.py", line 115, in _get_response
    response = self.process_exception_by_middleware(e, request)
  File "/Users/teecoin/PycharmProjects/recommender_env/lib/python3.7/site-packages/django/core/handlers/base.py", line 113, in _get_response
    response = wrapped_callback(request, *callback_args, **callback_kwargs)
  File "/Users/teecoin/PycharmProjects/recommender_env/lib/python3.7/site-packages/django/views/decorators/csrf.py", line 54, in wrapped_view
    return view_func(*args, **kwargs)
  File "/Users/teecoin/PycharmProjects/recommender_env/lib/python3.7/site-packages/django/views/generic/base.py", line 71, in view
    return self.dispatch(request, *args, **kwargs)
  File "/Users/teecoin/PycharmProjects/recommender_env/lib/python3.7/site-packages/rest_framework/views.py", line 505, in dispatch
    response = self.handle_exception(exc)
  File "/Users/teecoin/PycharmProjects/recommender_env/lib/python3.7/site-packages/rest_framework/views.py", line 465, in handle_exception
    self.raise_uncaught_exception(exc)
  File "/Users/teecoin/PycharmProjects/recommender_env/lib/python3.7/site-packages/rest_framework/views.py", line 476, in raise_uncaught_exception
    raise exc
  File "/Users/teecoin/PycharmProjects/recommender_env/lib/python3.7/site-packages/rest_framework/views.py", line 502, in dispatch
    response = handler(request, *args, **kwargs)
  File "/Users/teecoin/PycharmProjects/recommender_env/lib/python3.7/site-packages/rest_framework/decorators.py", line 50, in handler
    return func(*args, **kwargs)
  File "/Users/teecoin/PycharmProjects/recommender_system_api/recommender_system_api/api/views.py", line 44, in get_custom_page_recommendations
    vendor_id_arr, rating_df, vendor_cosine_sim, neural_net_model)
  File "/Users/teecoin/PycharmProjects/recommender_system_api/recommender_system_api/vendors/vendor_hybrid_recommendation.py", line 83, in specific_recommendation
    rating_df=rating_df, vendor_id=vendor_id)
  File "/Users/teecoin/PycharmProjects/recommender_system_api/recommender_system_api/vendors/user_profiles.py", line 39, in build_user_profile_cb
    idx = indices[indices == vendor_id].index[0]
  File "/Users/teecoin/PycharmProjects/recommender_env/lib/python3.7/site-packages/pandas/core/indexes/base.py", line 4280, in __getitem__
    return getitem(key)
IndexError: index 0 is out of bounds for axis 0 with size 0
ERROR 10/Oct/2019 09:40:33 basehttp [django.server:log_message:154] "GET /recommendation/custom/ HTTP/1.1" 500 27
INFO 10/Oct/2019 09:44:24 autoreload [django.utils.autoreload:trigger_reload:217] /Users/teecoin/PycharmProjects/recommender_system_api/recommender_system_api/api/views.py changed, reloading.
INFO 10/Oct/2019 09:44:25 autoreload [django.utils.autoreload:run_with_reloader:597] Watching for file changes with StatReloader
INFO 10/Oct/2019 09:44:40 basehttp [django.server:log_message:154] "GET /recommendation/custom/ HTTP/1.1" 200 364
INFO 10/Oct/2019 09:44:43 basehttp [django.server:log_message:154] "GET /recommendation/custom/ HTTP/1.1" 200 364
